Workbook

Sheet Overview
A1: JAVIER BLAS FRAMEWORK — MONITOR DELLE 4 TESI SULL'IRAN WAR & OIL
A2: Tracker aggiornabile delle metriche chiave — Bloomberg Opinion Apr-May 2026
A4: Tesi 1 — China's Invisible Hand
A5: Bloomberg Opinion · 8 Maggio 2026 | C5: La Cina sta silenziosamente tagliando le importazioni di petrolio — la 'mano invisibile' che riequilibra il mercato
A6: Metriche tracciate: | C6: China imports MoM, refinery runs, SPR fill rate, gasoline exports
A7: → vedi sheet: 'China Demand'
A8: Tesi 2 — US Supplier of Last Resort
A9: Bloomberg Opinion · 13 Maggio 2026 | C9: Le esportazioni USA hanno tenuto i prezzi bassi. Come Fed con i dollari, ma con limiti fisici
A10: Metriche tracciate: | C10: US crude exports, gasoline exports, production, days of supply
A11: → vedi sheet: 'US Exports'
A12: Tesi 3 — Europe's Unexpected Calm
A13: Bloomberg Opinion · 5 Maggio 2026 | C13: Nonostante lo shock petrolifero, i mercati elettrici europei sono calmi. Diverso dal 2022
A14: Metriche tracciate: | C14: TTF gas, power baseload, storage %, electricity bills proxy
A15: → vedi sheet: 'Europe Energy'
A16: Tesi 4 — Iran Not Exploding
A17: Bloomberg Opinion · 29 Aprile 2026 | C17: L'industria petrolifera iraniana NON sta implodendo nei tempi previsti da Trump
A18: Metriche tracciate: | C18: Iran production, exports, storage, shut-in wells, infrastructure
A19: → vedi sheet: 'Iran Production'
A22: UPDATE LOG
A23: Data | B23: Sheet | C23: Variabile | D23: Note | E23: New Value | F23: Fonte | G23: Note
A24: 2026-05-14 | B24: China Demand | C24: Crude Imp Mag '26: 7.0 → 8.5 mbd | D24: Blas (May 8): −25% from prewar 11.4 mbd ≈ 8.5 | F24: JPM, Vortexa, Bloomberg, IEA | G24: Baseline values from May 2026 sources
A25: 2026-05-14 | B25: US Exports | C25: Refinery Util: 97% → 91.7% | D25: EIA WPSR week May 8 — MAJOR REVISION
A26: 2026-05-14 | B26: US Exports | C26: Crude Exp: 6.5 → 4.8 mbd | D26: Net exports 5.9 mbd include refined products
A27: 2026-05-14 | B27: Europe Energy | C27: Storage: 58% → 33% | D27: AGSI+ May 1 — MAJOR REVISION
A28: 2026-05-14 | B28: Europe Energy | C28: Power: €115 → €70/MWh | D28: Blas (May 5): FR 1Y fwd €50/MWh
A29: 2026-05-14 | B29: Iran Production | C29: Perm Loss: 80 → 30 kbd | D29: Blas (Apr 29): no industry collapse
A30: 2026-05-17 | B30: ALL | C30: Added weekly row Mag-S2 '26 (week ending May 15) | D30: Source: IEA OMR May 2026 + EIA WPSR May 8 + AGSI+ mid-May + Trading Economics
A31: 2026-05-17 | B31: China Demand | C31: Crude Imp Mag-S2: 7.8 mbd (was 8.5 last update) | D31: IEA: -3.6 mbd Feb→Apr seaborne (massive revision)
A32: 2026-05-17 | B32: US Exports | C32: Crude exports 5.5 mbd (was 4.8); Refinery 91.7% | D32: EIA WPSR May 8: +0.742 mbpd exports week-on-week
A33: 2026-05-17 | B33: US Exports | C33: SPR drawdown -8.6 mbbls week to 341M bbl | D33: EIA WPSR May 8 — runway ~7 months to floor
A34: 2026-05-17 | B34: Europe Energy | C34: TTF €50, Storage 36%, Bills €60 → STRESS | D34: Storage rebuilding but TTF up 11% this week
A35: 2026-05-17 | B35: Iran Production | C35: 30 ships transited Hormuz this week | D35: Some recovery via 'Persian Gulf Strait Authority' protocol
A36: 2026-05-17 | B36: Market | C36: Brent $109/bbl (+8.1% WoW) | D36: IEA warns market undersupplied through October
... A85: 2026-09-12 | B85: Global | C85: IEA taglia la domanda 2026 di 2,5 mbd: maggior calo dal Covid | D85: Goldman alza le stime (Brent $85 a dicembre) ma avverte: oltre $120 nel 2027 se il Golfo resta 4 mbd sotto i livelli pre-guerra. HSBC a $90

Sheet Synthesis
A1: SYNTHESIS — LE 4 TESI IN UN COLPO D'OCCHIO
A2: Dashboard cross-tesi con cross-references vs sheet originali (aggiornare i sheet → questa pagina si aggiorna)
A4: Tesi | B4: Indicatore Chiave | C4: Latest | D4: Δ vs Feb '26 | E4: Status | F4: Conferma Tesi?
A5: 1. China invisible hand | B5: Total Crude Import (mbd) | C5: ='China Demand'!B22 -> 9.35 | D5: ='China Demand'!B22-'China Demand'!B10 -> -2.05 | E5: =IF('China Demand'!B22<10,"⬇ Demand destruction in atto","→ Ancora stabile") -> ⬇ Demand destruction in atto | F5: =IF('China Demand'!B22<10,"✓ CONFERMATA","✗ Non ancora") -> ✓ CONFERMATA
A6: 2. US supplier last resort | B6: Total Petroleum Exp (mbd) | C6: ='US Exports'!K22 -> 7.725 | D6: ='US Exports'!K22-'US Exports'!K10 -> 0.35 | E6: =IF('US Exports'!H22>0.95,"⚠ Max capacity raggiunto","→ Capacità ancora disponibile") -> ⚠ Max capacity raggiunto | F6: =IF('US Exports'!H22>0.95,"⚠ Limite raggiunto","✓ ANCORA VALIDA") -> ⚠ Limite raggiunto
A7: 3. Europe calm | B7: Power Bills Proxy (€/MWh) | C7: ='Europe Energy'!G22 -> 108 | D7: ='Europe Energy'!G22-'Europe Energy'!G10 -> 44 | E7: =IF(OR('Europe Energy'!G22>=100,'Europe Energy'!D22<0.7),"⛔ Crisi in formazione",IF(OR('Europe Energy'!G22>=80,'Europe Energy'!D22<0.8),"⚠ Tensione","✓ Calma persistente")) -> ⛔ Crisi in formazione | F7: =IF(OR('Europe Energy'!G22>=100,'Europe Energy'!D22<0.7),"✗ COMPROMESSA",IF(OR('Europe Energy'!G22>=80,'Europe Energy'!D22<0.8),"⚠ Sotto pressione","✓ CONFERMATA")) -> ✗ COMPROMESSA
A8: 4. Iran NOT exploding | B8: Permanent Loss (kbd) | C8: ='Iran Production'!G22 -> 130 | D8: ='Iran Production'!G22-'Iran Production'!G10 -> 129.65 | E8: =IF('Iran Production'!G22<200,"✓ Nessuna esplosione","⚠ Danni significativi") -> ✓ Nessuna esplosione | F8: =IF('Iran Production'!G22<500,"✓ CONFERMATA","✗ Tesi rotta") -> ✓ CONFERMATA
A11: INSIGHT INTEGRATO — DOVE VEGLIARE
A12: • Tesi 1 & 2 sono interconnesse: USA fornisce barili che potrebbero altrimenti causare panico in Asia, mentre Cina riduce domanda silenziosamente
A13: • Tesi 3 (Europe calm) può rompersi rapidamente se diesel crack spread supera $50/bbl (oggi: ~$42) — gas storage attuale fornisce 4-5 mesi di copertura
A14: • Tesi 4 (Iran non esplode) è la più solida nel breve: shut-in temporanei non causano damage permanente significativo entro 3-6 mesi
A15: • Il timing più rischioso è Giu-Lug '26: se Cina smette di ridurre domanda E USA raggiunge max capacity contemporaneamente, $200+ è prezzato in poche settimane
A16: • [Mysteel 18/5] Demand destruction Cina ha 2 componenti: ~30% strutturale (EV+policy) + ~70% ciclica (prezzi). Quando cease-fire arriva, solo 70% torna.
A17: • [Sentinel/UANI 16/5] 23 tanker accumulati a Kharg (vs 4 il 13/4) — Iran HA GIÀ raggiunto saturazione storage e sta tagliando produzione. Asimmetria temporale: Iran rotto subito, USA ha 5 mesi di runway.
A18: • [EOA/Salhajji 27/5] Scorte globali a 2.43 Bn bbl, +0.08 vs 2025 e +0.12 vs 2024. CONFUTA scenario shock acuto $130-150 nel breve. Range realistico Q3: $95-115/bbl. La crisi è di RISCHIO GEOPOLITICO non di SCARCITY FISICA.
A19: • [Scenari ricalibrati 28/5] Expected value Brent Q3 sceso da ~$118 a ~$105. Range $95-115. Asimmetria: downside rapido se cease-fire ($75-85), upside lento ma violento se escalation persiste ($140-180 in Q4). Vedi sheet 'Brent Scenarios'.
A20: 🔴 [29/5 SVOLTA] Accordo prelim. USA-Iran (MoU 60gg, Hormuz riapre). Brent CROLLA a $92 (−19% mese, peggior mese da 2020). Scenario A de-escalation MATERIALIZZA. Conferma asimmetria: scorte alte = collasso rapido come previsto dal modello.
A21: • [Salhajji 2-panel 1/6] Scorte alte 2026 sono fenomeno CINA+US (1.27 Bn, 52% del totale). Excluding China&US il mondo è a livelli NORMALI. Scorte cinesi NON fungibili per mercato globale → qualifica 'no shock'. Riconcilia Total alto con on-land tight IEA.
A22: 🔴 [12/6 DIVERGENZA ESTREMA] Brent $86.5 (min da marzo) su bozza accordo 14 punti (firma possibile weekend) MA fisico si stringe: SPR 350 (-66.2 dal pre-war, rate raddoppiato a -8/sett), commercial -7.2M, refinery 94.7%. Floor politico SPR 340 a 1-2 settimane. Se deal salta, upside violento; se firma, A completo verso $78.
... A32: 🔴 [12/9 LA SETTIMANA PEGGIORE] Brent $104,6 dopo il picco di $108 (massimo dal 19 maggio), settimana +8,7%. Il record di transiti del 31/8 è già rientrato: fra il 4 e il 9 settembre i passaggi commerciali a Hormuz sono scesi a UNA CIFRA al giorno e le uscite LNG quasi a zero. L'Iran annuncia una zona di esclusione fuori dallo stretto; gli USA hanno colpito 10 petroliere iraniane. Salta anche la seconda valvola: l'Arabia Saudita ha chiuso la pipeline East-West dopo ripetuti attacchi e gli Houthi sono arrivati a Perim. TTF oltre €80 per la prima volta da inizio 2023. Unica nota di apertura: vertice GCC-Iran in Oman lunedì.

Sheet China Demand
A1: CHINA DEMAND — L'Invisibile Mano della Domanda
A2: TESI: La Cina sta silenziosamente riducendo le importazioni — agente nascosto di riequilibrio del mercato
B3: IMPORTS BREAKDOWN | E3: ATTIVITÀ DOMESTICA | H3: METRICHE DERIVATE
A4: Mese | B4: TOTAL (mbd) | C4: Seaborne (mbd) | D4: Pipeline (mbd) | E4: Refinery Runs (mbd) | F4: SPR Build (kbd) | G4: Gasoline Exp. (kbd) | H4: Implied Demand (mbd) | I4: MoM Δ Total (mbd) | J4: Seaborne % | K4: Stato
A5: Gen '25 | B5: 11.3 | C5: 10.4 | D5: 0.9 | E5: 14.5 | F5: 200 | G5: 980 | H5: =E5-G5/1000-F5/1000 -> 13.32 | I5: — | J5: =C5/B5 -> 0.92035398 | K5: —
A6: Apr '25 | B6: 11.5 | C6: 10.6 | D6: 0.9 | E6: 14.7 | F6: 250 | G6: 1050 | H6: =E6-G6/1000-F6/1000 -> 13.4 | I6: =B6-B5 -> 0.2 | J6: =C6/B6 -> 0.92173913 | K6: =IF(I6<-1,"⬇ DESTRUCTION",IF(I6<-0.3,"⬇ Riduzione",IF(I6>0.3,"⬆ Crescita","→ Stabile"))) -> → Stabile
A7: Lug '25 | B7: 11.6 | C7: 10.7 | D7: 0.9 | E7: 14.8 | F7: 280 | G7: 1100 | H7: =E7-G7/1000-F7/1000 -> 13.42 | I7: =B7-B6 -> 0.1 | J7: =C7/B7 -> 0.92241379 | K7: =IF(I7<-1,"⬇ DESTRUCTION",IF(I7<-0.3,"⬇ Riduzione",IF(I7>0.3,"⬆ Crescita","→ Stabile"))) -> → Stabile
A8: Ott '25 | B8: 11.8 | C8: 10.9 | D8: 0.9 | E8: 14.9 | F8: 300 | G8: 1150 | H8: =E8-G8/1000-F8/1000 -> 13.45 | I8: =B8-B7 -> 0.2 | J8: =C8/B8 -> 0.92372881 | K8: =IF(I8<-1,"⬇ DESTRUCTION",IF(I8<-0.3,"⬇ Riduzione",IF(I8>0.3,"⬆ Crescita","→ Stabile"))) -> → Stabile
A9: Gen '26 | B9: 11.5 | C9: 10.6 | D9: 0.9 | E9: 14.6 | F9: 250 | G9: 1200 | H9: =E9-G9/1000-F9/1000 -> 13.15 | I9: =B9-B8 -> -0.3 | J9: =C9/B9 -> 0.92173913 | K9: =IF(I9<-1,"⬇ DESTRUCTION",IF(I9<-0.3,"⬇ Riduzione",IF(I9>0.3,"⬆ Crescita","→ Stabile"))) -> → Stabile
A10: Feb '26 | B10: 11.4 | C10: 10.5 | D10: 0.9 | E10: 14.5 | F10: 200 | G10: 1180 | H10: =E10-G10/1000-F10/1000 -> 13.12 | I10: =B10-B9 -> -0.1 | J10: =C10/B10 -> 0.92105263 | K10: =IF(I10<-1,"⬇ DESTRUCTION",IF(I10<-0.3,"⬇ Riduzione",IF(I10>0.3,"⬆ Crescita","→ Stabile"))) -> → Stabile
A11: Mar '26 | B11: 10.2 | C11: 9.2 | D11: 1 | E11: 13.2 | F11: -300 | G11: 1050 | H11: =E11-G11/1000-F11/1000 -> 12.45 | I11: =B11-B10 -> -1.2 | J11: =C11/B11 -> 0.90196078 | K11: =IF(I11<-1,"⬇ DESTRUCTION",IF(I11<-0.3,"⬇ Riduzione",IF(I11>0.3,"⬆ Crescita","→ Stabile"))) -> ⬇ DESTRUCTION
A12: Apr '26 | B12: 9 | C12: 6.9 | D12: 2.1 | E12: 12.5 | F12: -800 | G12: 950 | H12: =E12-G12/1000-F12/1000 -> 12.35 | I12: =B12-B11 -> -1.2 | J12: =C12/B12 -> 0.76666667 | K12: =IF(I12<-1,"⬇ DESTRUCTION",IF(I12<-0.3,"⬇ Riduzione",IF(I12>0.3,"⬆ Crescita","→ Stabile"))) -> ⬇ DESTRUCTION
A13: Mag '26 | B13: 8.5 | C13: 7.5 | D13: 1 | E13: 13.2 | F13: -200 | G13: 920 | H13: =E13-G13/1000-F13/1000 -> 12.48 | I13: =B13-B12 -> -0.5 | J13: =C13/B13 -> 0.88235294 | K13: =IF(I13<-1,"⬇ DESTRUCTION",IF(I13<-0.3,"⬇ Riduzione",IF(I13>0.3,"⬆ Crescita","→ Stabile"))) -> ⬇ Riduzione
A14: Mag-S2 '26 | B14: 8.7 | C14: 7.8 | D14: 0.9 | E14: 12.5 | F14: 300 | G14: 850 | H14: =E14-G14/1000-F14/1000 -> 11.35 | I14: =B14-B13 -> 0.2 | J14: =C14/B14 -> 0.89655172 | K14: =IF(I14<-1,"⬇ DESTRUCTION",IF(I14<-0.3,"⬇ Riduzione",IF(I14>0.3,"⬆ Crescita","→ Stabile"))) -> → Stabile
A15: Mag-S3 '26 | B15: 8.3 | C15: 8 | D15: 0.9 | E15: 12.8 | F15: 400 | G15: 870 | H15: =E15-G15/1000-F15/1000 -> 11.53 | I15: =B15-B14 -> -0.4 | J15: =C15/B15 -> 0.96385542 | K15: =IF(I15<-1,"⬇ DESTRUCTION",IF(I15<-0.3,"⬇ Riduzione",IF(I15>0.3,"⬆ Crescita","→ Stabile"))) -> ⬇ Riduzione
A16: Giu-S1 '26
A17: Lug-S1 '26 | B17: 9.5 | C17: 8.6 | D17: 0.9 | E17: 13.6 | F17: 650 | G17: 900 | H17: =E17-G17/1000-F17/1000 -> 12.05 | I17: =B17-B16 -> 9.5 | J17: =C17/B17 -> 0.90526316 | K17: =IF(I17<-1,"⬇ DESTRUCTION",IF(I17<-0.3,"⬇ Riduzione",IF(I17>0.3,"⬆ Crescita","→ Stabile"))) -> ⬆ Crescita
A18: Lug-S3 '26 | B18: 8.2 | C18: 7.3 | D18: 0.9 | E18: 13 | F18: -410 | G18: 880 | H18: =E18-G18/1000-F18/1000 -> 12.53 | I18: =B18-B17 -> -1.3 | J18: =C18/B18 -> 0.8902439 | K18: =IF(I18<-1,"⬇ DESTRUCTION",IF(I18<-0.3,"⬇ Riduzione",IF(I18>0.3,"⬆ Crescita","→ Stabile"))) -> ⬇ DESTRUCTION
A19: Ago-S2 '26 | B19: 8.6 | C19: 7.7 | D19: 0.9 | E19: 13.1 | F19: 120 | G19: 890 | H19: =E19-G19/1000-F19/1000 -> 12.09 | I19: =B19-B18 -> 0.4 | J19: =C19/B19 -> 0.89534884 | K19: =IF(I19<-1,"⬇ DESTRUCTION",IF(I19<-0.3,"⬇ Riduzione",IF(I19>0.3,"⬆ Crescita","→ Stabile"))) -> ⬆ Crescita
A20: Ago-S4 '26 | B20: 9.1 | C20: 8.2 | D20: 0.9 | E20: 13.4 | F20: 300 | G20: 760 | H20: =E20-G20/1000-F20/1000 -> 12.34 | I20: =B20-B19 -> 0.5 | J20: =C20/B20 -> 0.9010989 | K20: =IF(I20<-1,"⬇ DESTRUCTION",IF(I20<-0.3,"⬇ Riduzione",IF(I20>0.3,"⬆ Crescita","→ Stabile"))) -> ⬆ Crescita
A21: Set-S1 '26 | B21: 9.4 | C21: 8.55 | D21: 0.85 | E21: 13.5 | F21: 250 | G21: 790 | H21: =E21-G21/1000-F21/1000 -> 12.46 | I21: =B21-B20 -> 0.3 | J21: =C21/B21 -> 0.90957447 | K21: =IF(I21<-1,"⬇ DESTRUCTION",IF(I21<-0.3,"⬇ Riduzione",IF(I21>0.3,"⬆ Crescita","→ Stabile"))) -> → Stabile
A22: Set-S2 '26 | B22: 9.35 | C22: 8.5 | D22: 0.85 | E22: 13.45 | F22: 200 | G22: 780 | H22: =E22-G22/1000-F22/1000 -> 12.47 | I22: =B22-B21 -> -0.05 | J22: =C22/B22 -> 0.90909091 | K22: =IF(I22<-1,"⬇ DESTRUCTION",IF(I22<-0.3,"⬇ Riduzione",IF(I22>0.3,"⬆ Crescita","→ Stabile"))) -> → Stabile
A24: 📊 ANALISI BLAS — DECOMPOSIZIONE SEABORNE vs PIPELINE
A26: Seaborne crash Feb→Apr
A27: Pipeline absorbtion
A28: Net import change
A29: Seaborne % attuale
A32: NOTE METODOLOGICHE & FONTI
A33: • Col B 'Total' = China General Administration of Customs (GACC) — dato ufficiale mensile
A34: • Col C 'Seaborne' = IEA OMR + Kpler AIS tracking — esposto al blocco di Hormuz
A35: • Col D 'Pipeline' = ESPO (Russia) ~0.7-0.9 mbd + Atyrau-Alashankou (Kazakistan) ~0.2 mbd — immune al conflitto
A36: • Pre-guerra (Feb '26): Seaborne 92% del totale; durante crisi (Apr '26): scende a 77%
A37: • La pipeline russa è il proxy nascosto della sostituzione Cina/Russia (link Tesi 1 e Tesi 2 di Blas)
A38: • IEA OMR May 2026: 'Chinese seaborne crude imports fell by a massive 3.6 mb/d from February to April'
... A87: → MONITORARE: China gasoline retail demand weekly via Mysteel.

Sheet China SD Balance
A1: CHINA SUPPLY/DEMAND BALANCE — Crude, LPG, Refined Products
A2: Quadro integrato dei flussi petroliferi cinesi — fonti: Mysteel/OilChem, IEA OMR, China Customs
A4: 📥 SUPPLY SIDE — Imports per categoria (M tonnes mensili)
A6: Categoria | B6: Feb '26 (pre-war) | C6: Mar '26 | D6: Apr '26 | E6: Mag '26 (stima) | F6: Δ Feb→Apr | G6: Δ MoM Mar→Apr | H6: % YoY (Apr) | I6: Fonte | J6: Note | K6: Status
A7: Crude (totale) | B7: 48 | C7: 44 | D7: 38 | E7: 36 | F7: =D7-B7 -> -10 | G7: =(D7-C7)/C7 -> -0.13636364 | H7: — | I7: China Customs | J7: Total imports crude | K7: ⚠
A8: Crude seaborne | B8: 44 | C8: 38.5 | D8: 28.5 | E8: 33 | F8: =D8-B8 -> -15.5 | G8: =(D8-C8)/C8 -> -0.25974026 | H8: — | I8: IEA OMR May | J8: −3.6 mbd Feb→Apr | K8: ⬇
A9: Crude pipeline (RUS+KZ) | B9: 3.8 | C9: 4.3 | D9: 9 | E9: 3.8 | F9: =D9-B9 -> 5.2 | G9: =(D9-C9)/C9 -> 1.0930233 | H9: — | I9: IEA OMR | J9: Russia ESPO surge | K9: ⬆
A10: LPG (VLGC) | B10: 2.7 | C10: 2.6 | D10: 1.3 | E10: 1.4 | F10: =D10-B10 -> -1.4 | G10: =(D10-C10)/C10 -> -0.5 | H10: −58% | I10: Mysteel/OilChem | J10: Min storico 2017-18 | K10: ⬇
A11: Refined oil (export) | B11: 1.3 | C11: 1.2 | D11: 0.68 | E11: 0.8 | F11: =D11-B11 -> -0.62 | G11: =(D11-C11)/C11 -> -0.43333333 | H11: — | I11: OilChem 18/5 | J11: Beijing trattiene | K11: ⬇
A14: 📤 DEMAND SIDE — Consumo interno e segnali demand destruction
A16: Indicatore | B16: Feb '26 | C16: Mar '26 | D16: Apr '26 | E16: Mag '26 | F16: Trend | G16: Driver | H16: Note | I16: Fonte | J16: — | K16: Status
A17: Gasoline retail (pump) | B17: stabile | C17: stabile | D17: ↓ cap | E17: ↓ cap | F17: ▼ Price cap | G17: Sconto promo non bastano | H17: Mysteel: 'high prices cap demand' | I17: Mysteel 18/5 | J17: — | K17: ⬇
A18: Gasoil — Nord (wheat harv.) | B18: stabile | C18: stabile | D18: ↑ harvest | E18: ↑ harvest | F18: ▲ Stagionale | G18: Mietitura grano | H18: Demand temporanea + | I18: Mysteel 18/5 | J18: — | K18: ⬆
A19: Gasoil — Sud (fishing ban) | B19: stabile | C19: stabile | D19: ↓ ban | E19: ↓ ban | F19: ▼ Ban + piogge | G19: Coastal fishing ban | H19: Demand temporanea − | I19: Mysteel 18/5 | J19: — | K19: ⬇
A20: Heavy trucks — diesel | B20: alta | C20: media | D20: media | E20: ↓ | F20: ▼ EV substitution | G20: Trade-in policy favorisce EV | H20: EV +61% YoY (25,500 sets) | I20: Mysteel 18/5 | J20: — | K20: ⬇
A21: Heavy trucks — EV | B21: 10k | C21: 15k | D21: 25.5k | E21: 30k | F21: ▲ Boom | G21: Sussidio governativo | H21: Demand destruction STRUTTURALE | I21: Mysteel 18/5 | J21: — | K21: ⬆
A22: Petrochemical (naphtha) | B22: stabile | C22: leggermente ↓ | D22: ↓ | E22: ↓ | F22: ▼ Margini compressi | G22: Crude high vs PE/PP weak | H22: Cracker run rate sub-80% | I22: Stime | J22: — | K22: ⬇
A23: Aviation (jet fuel) | B23: ↑ Mar travel | C23: ↑ travel | D23: ↑ travel | E23: ↑ | F23: ▲ International recovery | G23: China outbound recovery | H23: Domanda jet resilient | I23: IEA | J23: — | K23: ⬆
A26: ⚖ BILANCIO NETTO — Implicazioni per modello globale
A27: 📍 STATO ATTUALE (Maggio 2026):
A28: • Cina ha ridotto IMPORT di ~3 mbd crude equivalent (Feb→Apr)
A29: • Solo ~30% della riduzione è strutturale (EV substitution + policy)
A30: • ~70% è ciclica (price-induced demand destruction)
A31: • Pipeline RUS+KZ ASSORBE ~1 mbd dei flussi seaborne persi
A33: 🔮 SCENARI FORWARD:
A35: SCENARIO A — Cease-fire entro luglio (probability 30%):
A36: → Cyclical demand torna in 2-3 mesi → Cina riassume +2 mbd entro ottobre
A37: → SPR USA drawdown si STABILIZZA al floor politico ~340 M bbl (settembre)
A38: → Brent si stabilizza a $90-100/bbl
A40: SCENARIO B — Stallo prolungato (probability 50%):
... A54: • LPG VLGC arrivals (Hormuz proxy specifico per gas)

Sheet Asia Demand + Pump
A1: ASIA DEMAND (Cina + India) & PREZZI ALLA POMPA GLOBALI — 22 luglio 2026
A2: I due maggiori importatori asiatici a confronto + trasmissione dei prezzi al consumatore finale
A4: 🇮🇳 INDIA — Il grande riposizionamento: da Golfo a Russia
A5: Metrica | B5: Pre-crisi (2025) | C5: Feb '26 | D5: Mar '26 | E5: Giu '26 | F5: Lug '26 | G5: Δ vs pre-crisi | H5: Trend | I5: Fonte | J5: Note
A6: Import totali (mbd) | B6: 4.9 | C6: 4.6 | D6: 4.3 | E6: 5 | F6: 5.1 | G6: =F6-B6 -> 0.2 | H6: ⬆ | I6: Kpler | J6: Luglio supera 5 mbd: refiner fanno scorta ante-sanzioni
A7: da Russia (mbd) | B7: 1.7 | C7: 1.07 | D7: 1.79 | E7: 2.6 | F7: 2.55 | G7: =F7-B7 -> 0.85 | H7: ⬆⬆ | I7: Kpler | J7: ~50% del basket. 'Hedge di sicurezza energetica' post-Hormuz
A8: da Golfo via Hormuz (mbd) | B8: 2.55 | C8: 2.3 | D8: 1.5 | E8: 1.5 | F8: 1.53 | G8: =F8-B8 -> -1.02 | H8: ⬇⬇ | I8: S&P CAS | J8: Quota Golfo da ~50% a ~30% del totale
A9: da USA (kbd) | B9: 180 | C9: 160 | D9: 150 | E9: 157 | F9: 56 | G9: =F9-B9 -> -124 | H9: ⬇ | I9: Kpler | J9: Crollo: i barili russi scontati battono l'Atlantico lungo
A10: Export prodotti (mbd) | B10: 1.1 | C10: 1 | D10: 1.05 | E10: 1.2 | F10: 1.4 | G10: =F10-B10 -> 0.3 | H10: ⬆⬆ | I10: Kpler | J10: Massimo da settembre: +50% vs maggio, margini forti
A12: ⚖ CINA vs INDIA — Due strategie opposte di fronte allo stesso shock
A13: Dimensione | B13: 🇨🇳 CINA | F13: 🇮🇳 INDIA
A14: Strategia | B14: DEMAND DESTRUCTION | F14: DIVERSIFICAZIONE SUPPLY
A15: Import vs pre-crisi | B15: −3.1 mbd (da 11.3 a 8.2) | F15: +0.2 mbd (da 4.9 a 5.1)
A16: Fonte sostitutiva | B16: Pipeline Russia/Kazakh (ESPO) | F16: Seaborne Russia (Urals scontato)
A17: Esposizione Hormuz | B17: Ridotta a ~45% import | F17: Ridotta da ~52% a ~30%
A18: Leva sui prezzi | B18: Taglia domanda → raffredda mercato | F18: Compra tutto → sostiene domanda
A19: Effetto su Iran | B19: LEVA DIRETTA (99% export iraniano) | F19: Nessuna (non compra iraniano)
A20: Politica interna | B20: Sussidi EV, freno consumi | F20: Prezzi pompa amministrati, elezioni
A22: ⛽ PREZZI ALLA POMPA — Trasmissione al consumatore finale (USD/litro)
A23: Paese / Area | B23: Benzina pre-crisi | C23: Benzina 22 lug | D23: Δ % | E23: Diesel pre-crisi | F23: Diesel 22 lug | G23: Δ % | H23: Meccanismo | I23: Stress sociale | J23: Note
A24: Italia | B24: 1.75 | C24: 2.28 | D24: =(C24-B24)/B24 -> 0.30285714 | E24: 1.68 | F24: 2.35 | G24: =(F24-E24)/E24 -> 0.39880952 | H24: Mercato + accise | I24: ⚠ ALTO | J24: Accise fisse amplificano; diesel sopra benzina
A25: Germania | B25: 1.72 | C25: 2.22 | D25: =(C25-B25)/B25 -> 0.29069767 | E25: 1.66 | F25: 2.32 | G25: =(F25-E25)/E25 -> 0.39759036 | H25: Mercato | I25: ⚠ ALTO | J25: Diesel volatile, industria esposta
A26: Irlanda | B26: 1.85 | C26: 2.35 | D26: =(C26-B26)/B26 -> 0.27027027 | E26: 1.78 | F26: 2.4 | G26: =(F26-E26)/E26 -> 0.34831461 | H26: Mercato | I26: ⚠ ALTO | J26: Tra i più cari UE (EUR 1.98/l già a marzo)
A27: USA | B27: 0.92 | C27: 1.28 | D27: =(C27-B27)/B27 -> 0.39130435 | E27: 1.02 | F27: 1.42 | G27: =(F27-E27)/E27 -> 0.39215686 | H27: Mercato | I27: → MEDIO | J27: STEO: retail ~$3.80/gal 3Q26; protetto da shale
A28: India | B28: 1.28 | C28: 1.42 | D28: =(C28-B28)/B28 -> 0.109375 | E28: 1.16 | F28: 1.32 | G28: =(F28-E28)/E28 -> 0.13793103 | H28: Amministrato | I28: → CONTENUTO | J28: Governo assorbe con accise; ma fiscalità sotto pressione
A29: Cina | B29: 1.2 | C29: 1.3 | D29: =(C29-B29)/B29 -> 0.083333333 | E29: 1.05 | F29: 1.18 | G29: =(F29-E29)/E29 -> 0.12380952 | H29: Amministrato + cap | I29: ✓ BASSO | J29: Price cap: 'sconti alle pompe non bastano' (Mysteel)
A30: Media globale (175 pp) | B30: 1.3 | C30: 1.62 | D30: =(C30-B30)/B30 -> 0.24615385 | E30: 1.22 | F30: 1.55 | G30: =(F30-E30)/E30 -> 0.2704918 | H30: Misto | I30: ⚠ ALTO | J30: GlobalPetrolPrices weighted avg
A32: 💡 LA DIVERGENZA POMPA — Chi assorbe lo shock e chi lo trasferisce
A33: Il prezzo alla pompa è il canale attraverso cui il conflitto diventa POLITICA INTERNA. Tre modelli distinti:
A35: • MERCATO PURO (UE, USA): trasmissione rapida e completa. L'Europa paga il prezzo globale anche senza
A36: comprare greggio iraniano; le accise fisse amplificano l'impatto percentuale sui consumatori.
A37: Il diesel è il vero problema: crack elevati + esposizione industriale/trasporti.
A39: • AMMINISTRATO (India): il governo assorbe parte dello shock via leva fiscale, ma il costo si sposta
A40: sul bilancio pubblico. Sostenibile nel breve, insostenibile se il conflitto dura.
A42: • CAP + SUSSIDI (Cina): prezzi contenuti MA con demand destruction indotta — i consumatori riducono
A43: l'uso nonostante gli sconti promozionali. È il meccanismo che alimenta la 'mano invisibile' di Blas.
A45: → IMPLICAZIONE PER IL FRAMEWORK: la Tesi 3 (Europe's calm) va riletta. La calma dei mercati ELETTRICI
A46: regge (gas e rinnovabili), ma la calma SOCIALE si sta erodendo attraverso il canale carburanti.
A47: Il diesel europeo è oggi l'indicatore più politicamente sensibile del framework.
A49: Fonti: GlobalPetrolPrices.com (13-20 lug 2026) · IRU · EIA STEO luglio · Kpler · S&P Commodities at Sea · Mysteel. Valori pompa: stime elaborate su base pubblica, indicativi del trend.

Sheet US Exports
A1: US EXPORTS — Il Fornitore di Ultima Istanza
A2: TESI: Gli USA sono diventati 'supplier of last resort' — focus destinazioni Asia/Europa/Latam
B3: PROD. | C3: CRUDE EXPORTS BY DESTINATION | G3: REFINED & CAPACITY | I3: SPR | K3: METRICHE DERIVATE
A4: Mese | B4: Production (mbd) | C4: TOTAL Crude Exp. (mbd) | D4: Asia-Pac (mbd) | E4: Europa (mbd) | F4: Latam+Other (mbd) | G4: Gasoline Exp. (kbd) | H4: Refinery Util. (%) | I4: SPR Level (M bbl) | J4: SPR Δ (kbd) | K4: Total Petr. Exp. (mbd) | L4: Asia % | M4: Status
A5: Gen '25 | B5: 13.2 | C5: 4.2 | D5: 1.5 | E5: 1.6 | F5: 1.1 | G5: 800 | H5: 0.89 | I5: 395 | J5: -0.5 | K5: =C5+(G5*2.5)/1000 -> 6.2 | L5: =D5/C5 -> 0.35714286 | M5: =IF(H5>0.95,"⚠ MAX CAPACITY",IF(H5>0.92,"⬆ Surge attivo","→ Normale")) -> → Normale
A6: Apr '25 | B6: 13.3 | C6: 4.5 | D6: 1.6 | E6: 1.7 | F6: 1.2 | G6: 850 | H6: 0.91 | I6: 398 | J6: -0.5 | K6: =C6+(G6*2.5)/1000 -> 6.625 | L6: =D6/C6 -> 0.35555556 | M6: =IF(H6>0.95,"⚠ MAX CAPACITY",IF(H6>0.92,"⬆ Surge attivo","→ Normale")) -> → Normale
A7: Lug '25 | B7: 13.4 | C7: 4.7 | D7: 1.65 | E7: 1.8 | F7: 1.25 | G7: 880 | H7: 0.92 | I7: 402 | J7: 0 | K7: =C7+(G7*2.5)/1000 -> 6.9 | L7: =D7/C7 -> 0.35106383 | M7: =IF(H7>0.95,"⚠ MAX CAPACITY",IF(H7>0.92,"⬆ Surge attivo","→ Normale")) -> → Normale
A8: Ott '25 | B8: 13.4 | C8: 4.8 | D8: 1.7 | E8: 1.8 | F8: 1.3 | G8: 900 | H8: 0.91 | I8: 406 | J8: 0 | K8: =C8+(G8*2.5)/1000 -> 7.05 | L8: =D8/C8 -> 0.35416667 | M8: =IF(H8>0.95,"⚠ MAX CAPACITY",IF(H8>0.92,"⬆ Surge attivo","→ Normale")) -> → Normale
A9: Gen '26 | B9: 13.5 | C9: 4.9 | D9: 1.75 | E9: 1.85 | F9: 1.3 | G9: 920 | H9: 0.9 | I9: 408 | J9: -0.3 | K9: =C9+(G9*2.5)/1000 -> 7.2 | L9: =D9/C9 -> 0.35714286 | M9: =IF(H9>0.95,"⚠ MAX CAPACITY",IF(H9>0.92,"⬆ Surge attivo","→ Normale")) -> → Normale
A10: Feb '26 | B10: 13.5 | C10: 5 | D10: 1.8 | E10: 1.85 | F10: 1.35 | G10: 950 | H10: 0.9 | I10: 411 | J10: 0 | K10: =C10+(G10*2.5)/1000 -> 7.375 | L10: =D10/C10 -> 0.36 | M10: =IF(H10>0.95,"⚠ MAX CAPACITY",IF(H10>0.92,"⬆ Surge attivo","→ Normale")) -> → Normale
A11: Mar '26 | B11: 13.6 | C11: 5.2 | D11: 2.2 | E11: 2 | F11: 1 | G11: 1050 | H11: 0.94 | I11: 413 | J11: -1 | K11: =C11+(G11*2.5)/1000 -> 7.825 | L11: =D11/C11 -> 0.42307692 | M11: =IF(H11>0.95,"⚠ MAX CAPACITY",IF(H11>0.92,"⬆ Surge attivo","→ Normale")) -> ⬆ Surge attivo
A12: Apr '26 | B12: 13.7 | C12: 4.8 | D12: 2.5 | E12: 1.5 | F12: 0.8 | G12: 1200 | H12: 0.96 | I12: 397.9 | J12: -7.1 | K12: =C12+(G12*2.5)/1000 -> 7.8 | L12: =D12/C12 -> 0.52083333 | M12: =IF(H12>0.95,"⚠ MAX CAPACITY",IF(H12>0.92,"⬆ Surge attivo","→ Normale")) -> ⚠ MAX CAPACITY
A13: Mag '26 | B13: 13.65 | C13: 4.8 | D13: 2.45 | E13: 1.5 | F13: 0.85 | G13: 1100 | H13: 0.917 | I13: 391 | J13: -2 | K13: =C13+(G13*2.5)/1000 -> 7.55 | L13: =D13/C13 -> 0.51041667 | M13: =IF(H13>0.95,"⚠ MAX CAPACITY",IF(H13>0.92,"⬆ Surge attivo","→ Normale")) -> → Normale
A14: Mag-S2 '26 | B14: 13.7 | C14: 5.5 | D14: 2.8 | E14: 1.7 | F14: 1 | G14: 1150 | H14: 0.917 | I14: 384.1 | J14: -2.3 | K14: =C14+(G14*2.5)/1000 -> 8.375 | L14: =D14/C14 -> 0.50909091 | M14: =IF(H14>0.95,"⚠ MAX CAPACITY",IF(H14>0.92,"⬆ Surge attivo","→ Normale")) -> → Normale
A15: Mag-S3 '26 | B15: 13.7 | C15: 5.2 | D15: 2.5 | E15: 1.7 | F15: 1 | G15: 1150 | H15: 0.947 | I15: 357.1 | J15: -13.5 | K15: =C15+(G15*2.5)/1000 -> 8.075 | L15: =D15/C15 -> 0.48076923 | M15: =IF(H15>0.95,"⚠ MAX CAPACITY",IF(H15>0.92,"⬆ Surge attivo","→ Normale")) -> ⬆ Surge attivo
A16: Giu-S1 '26
A17: Lug-S1 '26 | B17: 13.75 | C17: 4.5 | D17: 2 | E17: 1.5 | F17: 1 | G17: 1200 | H17: 0.948 | I17: 325.7 | J17: -5.5 | K17: =C17+(G17*2.5)/1000 -> 7.5 | L17: =D17/C17 -> 0.44444444 | M17: =IF(H17>0.95,"⚠ MAX CAPACITY",IF(H17>0.92,"⬆ Surge attivo","→ Normale")) -> ⬆ Surge attivo
A18: Lug-S3 '26 | B18: 13.8 | C18: 4.8 | D18: 2.2 | E18: 1.6 | F18: 1 | G18: 1180 | H18: 0.952 | I18: 318 | J18: -2 | K18: =C18+(G18*2.5)/1000 -> 7.75 | L18: =D18/C18 -> 0.45833333 | M18: =IF(H18>0.95,"⚠ MAX CAPACITY",IF(H18>0.92,"⬆ Surge attivo","→ Normale")) -> ⚠ MAX CAPACITY
A19: Ago-S2 '26 | B19: 13.85 | C19: 4.6 | D19: 2.1 | E19: 1.55 | F19: 0.95 | G19: 1170 | H19: 0.943 | I19: 304.8 | J19: -2.8 | K19: =C19+(G19*2.5)/1000 -> 7.525 | L19: =D19/C19 -> 0.45652174 | M19: =IF(H19>0.95,"⚠ MAX CAPACITY",IF(H19>0.92,"⬆ Surge attivo","→ Normale")) -> ⬆ Surge attivo
A20: Ago-S4 '26 | B20: 13.9 | C20: 4.4 | D20: 1.95 | E20: 1.6 | F20: 0.85 | G20: 1210 | H20: 0.961 | I20: 296 | J20: -2.5 | K20: =C20+(G20*2.5)/1000 -> 7.425 | L20: =D20/C20 -> 0.44318182 | M20: =IF(H20>0.95,"⚠ MAX CAPACITY",IF(H20>0.92,"⬆ Surge attivo","→ Normale")) -> ⚠ MAX CAPACITY
A21: Set-S1 '26 | B21: 13.95 | C21: 4.55 | D21: 2.05 | E21: 1.6 | F21: 0.9 | G21: 1220 | H21: 0.958 | I21: 293 | J21: -1.5 | K21: =C21+(G21*2.5)/1000 -> 7.6 | L21: =D21/C21 -> 0.45054945 | M21: =IF(H21>0.95,"⚠ MAX CAPACITY",IF(H21>0.92,"⬆ Surge attivo","→ Normale")) -> ⚠ MAX CAPACITY
A22: Set-S2 '26 | B22: 14 | C22: 4.65 | D22: 2.1 | E22: 1.65 | F22: 0.9 | G22: 1230 | H22: 0.962 | I22: 291 | J22: -1 | K22: =C22+(G22*2.5)/1000 -> 7.725 | L22: =D22/C22 -> 0.4516129 | M22: =IF(H22>0.95,"⚠ MAX CAPACITY",IF(H22>0.92,"⬆ Surge attivo","→ Normale")) -> ⚠ MAX CAPACITY
A24: 📊 ANALISI BLAS — DOVE VANNO I BARILI USA (Atlantic Basin Pivot)
A26: Total exports surge Feb→curr
A27: Asia-Pacific pivot
A28: Europa shift
A29: Asia % attuale
A30: Refinery margin to max
A31: SPR runway (mesi)
A32: Data stimata raggiungimento Floor
A35: NOTE METODOLOGICHE & FONTI
A36: • Col D 'Asia-Pac' = export verso Corea Sud, Giappone, India, Taiwan, Singapore — sostituiscono crude Gulf
A37: • Col E 'Europa' = UE-27 + UK + Norvegia — recipient storico di crude WTI/Bakken
A38: • Col F 'Latam+Other' = Canada, Brazil, America Latina, Africa — flussi marginali
... A45: Storico settimanale + proiezione lineare al ritmo della media mobile 4 settimane
A47: Settimana | B47: SPR Storico (M bbl) | C47: SPR Proiettato | D47: Floor (280) | E47: SPR Level (M bbl)
A48: Mar 22 | B48: 411 | D48: 280 | E48: 411
A49: Mar 29 | B49: 409 | D49: 280 | E49: 409
A50: Apr 05 | B50: 406.5 | D50: 280 | E50: 406.5
A51: Apr 12 | B51: 402 | D51: 280 | E51: 402
...

Sheet Iran Production
A1: IRAN PRODUCTION — Non Sta 'Esplodendo' (vs Trump)
A2: TESI: L'industria petrolifera iraniana NON sta implodendo nei tempi previsti da Trump — focus seaborne vs onshore
B3: PROD. | C3: EXPORTS BREAKDOWN | F3: STORAGE | H3: DAMAGE | J3: METRICHE DERIVATE
A4: Mese | B4: Production (mbd) | C4: TOTAL Exp. (mbd) | D4: Seaborne (mbd) | E4: Land/Pipe (mbd) | F4: Storage (M bbl) | G4: Storage % | H4: Wells SI (%) | I4: Perm Loss (kbd) | J4: Floating St. (M bbl) | K4: Seaborne % | L4: Status
A5: Gen '25 | B5: 3.2 | C5: 1.5 | D5: 1.4 | E5: 0.1 | F5: 25 | G5: =F5/80 -> 0.3125 | H5: 0 | I5: 0 | J5: 30 | K5: =D5/C5 -> 0.93333333 | L5: =IF(I5>500,"⚠ Parz. vero",IF(I5>200,"⚠ Da monitorare","✗ Falso")) -> ✗ Falso
A6: Apr '25 | B6: 3.25 | C6: 1.55 | D6: 1.42 | E6: 0.13 | F6: 28 | G6: =F6/80 -> 0.35 | H6: 0 | I6: 0 | J6: 35 | K6: =D6/C6 -> 0.91612903 | L6: =IF(I6>500,"⚠ Parz. vero",IF(I6>200,"⚠ Da monitorare","✗ Falso")) -> ✗ Falso
A7: Lug '25 | B7: 3.3 | C7: 1.6 | D7: 1.45 | E7: 0.15 | F7: 30 | G7: =F7/80 -> 0.375 | H7: 0 | I7: 0 | J7: 32 | K7: =D7/C7 -> 0.90625 | L7: =IF(I7>500,"⚠ Parz. vero",IF(I7>200,"⚠ Da monitorare","✗ Falso")) -> ✗ Falso
A8: Ott '25 | B8: 3.3 | C8: 1.55 | D8: 1.4 | E8: 0.15 | F8: 32 | G8: =F8/80 -> 0.4 | H8: 0 | I8: 0 | J8: 35 | K8: =D8/C8 -> 0.90322581 | L8: =IF(I8>500,"⚠ Parz. vero",IF(I8>200,"⚠ Da monitorare","✗ Falso")) -> ✗ Falso
A9: Gen '26 | B9: 3.3 | C9: 1.5 | D9: 1.35 | E9: 0.15 | F9: 35 | G9: =F9/80 -> 0.4375 | H9: 0 | I9: 0 | J9: 38 | K9: =D9/C9 -> 0.9 | L9: =IF(I9>500,"⚠ Parz. vero",IF(I9>200,"⚠ Da monitorare","✗ Falso")) -> ✗ Falso
A10: Feb '26 | B10: 3.35 | C10: 2.2 | D10: 2.05 | E10: 0.15 | F10: 28 | G10: =F10/80 -> 0.35 | H10: 0 | I10: 0 | J10: 25 | K10: =D10/C10 -> 0.93181818 | L10: =IF(I10>500,"⚠ Parz. vero",IF(I10>200,"⚠ Da monitorare","✗ Falso")) -> ✗ Falso
A11: Mar '26 | B11: 3.1 | C11: 1.8 | D11: 1.55 | E11: 0.25 | F11: 50 | G11: =F11/80 -> 0.625 | H11: 0.05 | I11: 0 | J11: 55 | K11: =D11/C11 -> 0.86111111 | L11: =IF(I11>500,"⚠ Parz. vero",IF(I11>200,"⚠ Da monitorare","✗ Falso")) -> ✗ Falso
A12: Apr '26 | B12: 2.9 | C12: 1.4 | D12: 1.05 | E12: 0.35 | F12: 65 | G12: =F12/80 -> 0.8125 | H12: 0.2 | I12: 50 | J12: 72 | K12: =D12/C12 -> 0.75 | L12: =IF(I12>500,"⚠ Parz. vero",IF(I12>200,"⚠ Da monitorare","✗ Falso")) -> ✗ Falso
A13: Mag '26 | B13: 3 | C13: 1.1 | D13: 0.75 | E13: 0.35 | F13: 60 | G13: =F13/80 -> 0.75 | H13: 0.1 | I13: 30 | J13: 65 | K13: =D13/C13 -> 0.68181818 | L13: =IF(I13>500,"⚠ Parz. vero",IF(I13>200,"⚠ Da monitorare","✗ Falso")) -> ✗ Falso
A14: Mag-S2 '26 | B14: 2.75 | C14: 0.7 | D14: 0.5 | E14: 0.2 | F14: 72 | G14: =F14/80 -> 0.9 | H14: 0.2 | I14: 40 | J14: 75 | K14: =D14/C14 -> 0.71428571 | L14: =IF(I14>500,"⚠ Parz. vero",IF(I14>200,"⚠ Da monitorare","✗ Falso")) -> ✗ Falso
A15: Mag-S3 '26 | B15: 2.85
A16: Giu-S1 '26 | B16: 2.9 | C16: 1.2 | D16: 1 | E16: 0.2 | F16: 64 | G16: 40 | H16: 0.12 | I16: =F16/80 -> 0.8 | J16: 60 | K16: =D16/C16 -> 0.83333333 | L16: =IF(G16>500,"⚠ Parz. vero",IF(G16>200,"⚠ Da monitorare","✗ Falso")) -> ✗ Falso
A17: Lug-S1 '26 | B17: 3.1 | C17: 1.6 | D17: 1.4 | E17: 0.2 | F17: 55 | G17: 40 | H17: 0.08 | I17: =F17/80 -> 0.6875 | J17: 40 | K17: =D17/C17 -> 0.875 | L17: =IF(G17>500,"⚠ Parz. vero",IF(G17>200,"⚠ Da monitorare","✗ Falso")) -> ✗ Falso
A18: Lug-S3 '26 | B18: 2.6 | C18: 0.9 | D18: 0.7 | E18: 0.2 | F18: 66 | G18: 90 | H18: 0.22 | I18: =F18/80 -> 0.825 | J18: 70 | K18: =D18/C18 -> 0.77777778 | L18: =IF(G18>500,"⚠ Parz. vero",IF(G18>200,"⚠ Da monitorare","✗ Falso")) -> ✗ Falso
A19: Ago-S2 '26 | B19: 2.7 | C19: 1.05 | D19: 0.85 | E19: 0.2 | F19: 63 | G19: 95 | H19: 0.2 | I19: =F19/80 -> 0.7875 | J19: 65 | K19: =D19/C19 -> 0.80952381 | L19: =IF(G19>500,"⚠ Parz. vero",IF(G19>200,"⚠ Da monitorare","✗ Falso")) -> ✗ Falso
A20: Ago-S4 '26 | B20: 2.8 | C20: 1.15 | D20: 0.95 | E20: 0.2 | F20: 60 | G20: 95 | H20: 0.18 | I20: =F20/80 -> 0.75 | J20: 58 | K20: =D20/C20 -> 0.82608696 | L20: =IF(G20>500,"⚠ Parz. vero",IF(G20>200,"⚠ Da monitorare","✗ Falso")) -> ✗ Falso
A21: Set-S1 '26 | B21: 2.65 | C21: 0.95 | D21: 0.75 | E21: 0.2 | F21: 64 | G21: 105 | H21: 0.22 | I21: =F21/80 -> 0.8 | J21: 62 | K21: =D21/C21 -> 0.78947368 | L21: =IF(G21>500,"⚠ Parz. vero",IF(G21>200,"⚠ Da monitorare","✗ Falso")) -> ✗ Falso
A22: Set-S2 '26 | B22: 2.45 | C22: 0.7 | D22: 0.52 | E22: 0.18 | F22: 68 | G22: 130 | H22: 0.28 | I22: =F22/80 -> 0.85 | J22: 72 | K22: =D22/C22 -> 0.74285714 | L22: =IF(G22>500,"⚠ Parz. vero",IF(G22>200,"⚠ Da monitorare","✗ Falso")) -> ✗ Falso
A23: Trump 26/04
A25: 📊 ANALISI BLAS — DECOMPOSIZIONE SEABORNE vs LAND (T+45)
A27: Seaborne export crash Feb→curr
A28: Land route absorption
A29: Floating storage build
A30: Seaborne export % attuale
A31: Permanent vs Total export loss
A32: Production resilience
A35: NOTE METODOLOGICHE & FONTI
A36: • Col D 'Seaborne' = export via tanker da Kharg Island + altre Hormuz facilities — esposto al blocco navale USA
A37: • Col E 'Land/Pipe' = export terrestri Iraq swap (~100kbd), Pakistan smuggling, + Goreh-Jask bypass — immune al blocco
A38: • Col J 'Floating Storage' = greggio caricato ma non consegnato (dark fleet floating) — revenue differita ma non persa
... A55: 🎯 METRICHE OPERATIVE CHIAVE — Conteggio fisico verificato satellite
A57: Tanker buildup | C57: +475% | F57: Da 4 (13/4) a 23 (16/5) | I57: Storage iraniano in saturazione progressiva — Iran costretto a slowdown produzione
A60: Export collapse | C60: −80% | F60: Vortexa 13-25 aprile | I60: Solo numero limitato di tanker carichi di petrolio iraniano sono usciti dal Golfo dell'Oman
A63: Vessel inspections
A66: Floating storage
A71: ⚖ INSIGHT INTEGRATO — LA GARA TIME-CRITICAL TRA SPR USA E STORAGE IRAN
...

Sheet SHIP Act + OPEC
A1: DATI UFFICIALI — SHIP Act Report (EIA) + OPEC MOMR Giugno 2026
A2: Integrazione di due fonti primarie ufficiali: serie storica export Iran (Vortexa via EIA) + bilanci OECD stocks/supply (OPEC)
M3: ▶ Grafico export Iran vs Cina 2018-2025 →
A4: 📊 SHIP ACT (EIA, giugno 2026) — Export petrolio Iran 2018-2025, fonte Vortexa
A5: Metrica (kbd / $bn) | B5: 2018 | C5: 2019 | D5: 2020 | E5: 2021 | F5: 2022 | G5: 2023 | H5: 2024 | I5: 2025 | J5: Trend | K5: Note
A6: Export totale (Vortexa) | B6: 1976 | C6: 651 | D6: 343 | E6: 808 | F6: 923 | G6: 1276 | H6: 1445 | I6: 1576 | J6: ⬆ | K6: Recupero post-2020 a max 8 anni
A7: Export verso Cina | B7: 609 | C7: 315 | D7: 287 | E7: 658 | F7: 757 | G7: 1124 | H7: 1384 | I7: 1567 | J7: ⬆⬆ | K7: 99.4% del totale nel 2025!
A8: Export NON-Cina | B8: 1367 | C8: 337 | D8: 56 | E8: 151 | F8: 166 | G8: 151 | H8: 60 | I8: 9 | J8: ⬇⬇ | K8: Crollato: Cina assorbe tutto
A9: Revenue ($bn nominali) | B9: 51 | C9: 11 | D9: 5 | E9: 19 | F9: 38 | G9: 43 | H9: 49 | I9: 48 | J9: → | K9: Stabile ~$48-49bn nonostante sconti
A10: % Export verso Cina | B10: 0.32 | C10: 0.48 | D10: 0.84 | E10: 0.81 | F10: 0.82 | G10: 0.88 | H10: 0.96 | I10: 0.99 | J10: ⬆⬆ | K10: Iran = quasi 100% dipendente dalla Cina
A12: 🎯 INSIGHT SHIP ACT — La dipendenza totale Iran→Cina
A13: Il dato SHIP Act 2026 rivela la trasformazione strutturale dell'export iraniano negli ultimi 8 anni:
A15: • 2018 (pre-sanzioni piene): export 1.976 kbd, di cui solo 31% verso Cina — mercato diversificato
A16: • 2025 (oggi): export 1.576 kbd, di cui 99.4% verso Cina (1.567 kbd) — mono-cliente totale
A17: • Export NON-Cina CROLLATO da 1.367 kbd (2018) a 9 kbd (2025): -99.3%
A19: → IMPLICAZIONE CRITICA per Tesi 4 (Iran NOT exploding):
A20: La resilienza iraniana dipende interamente dalla Cina. Se Pechino riduce import (come sta facendo,
A21: vedi sheet China Demand), Iran NON ha mercati alternativi. La 'mano invisibile' cinese di Blas è
A22: quindi anche una LEVA su Teheran: la demand destruction cinese colpisce Iran più di chiunque altro.
A24: • Revenue 2025 ~$48bn nonostante volumi alti = conferma sconti $8-10/bbl su Iranian Light (gen 2026)
A25: • Flotta ombra: SHIP Act lista ~280 navi VLCC+/Suezmax/Aframax coinvolte (Appendici B-C)
M27: ▶ Grafico divergenza oil-on-water vs onland →
A28: 🛢 OPEC MOMR (giugno 2026) — OECD stocks & oil-on-water (mb)
A29: Categoria (mb) | B29: 2023 | C29: 2024 | D29: 2025 | E29: 3Q25 | F29: 4Q25 | G29: 1Q26 | H29: Δ 4Q25→1Q26 | I29: Stato | K29: Note
A30: OECD onland commercial | B30: 2780.3 | C30: 2755.8 | D30: 2826.6 | E30: 2868.7 | F30: 2826.6 | G30: 2796 | H30: =G30-F30 -> -30.6 | I30: ⬇ scende
A31: OECD SPR | B31: 1206.7 | C31: 1245.3 | D31: 1248.7 | E31: 1237.7 | F31: 1248.7 | G31: 1239.6 | H31: =G31-F31 -> -9.1 | I31: → stabile
A32: OECD total | B32: 3987 | C32: 4001.1 | D32: 4075.3 | E32: 4106.3 | F32: 4075.3 | G32: 4035.6 | H32: =G32-F32 -> -39.7 | I32: ⬇ scende
A33: Oil-on-water | B33: 1390.5 | C33: 1309.9 | D33: 1545.7 | E33: 1460.7 | F33: 1545.7 | G33: 1297.5 | H33: =G33-F33 -> -248.2 | I33: ⬇⬇ CROLLO
A35: ⚖ RICONCILIAZIONE FINALE — Oil-on-water è la chiave di tutto
A36: Il dato OPEC oil-on-water conferma e quantifica esattamente la nostra tesi della settimana scorsa:
A38: • Oil-on-water: 4Q25 = 1.545,7 mb → 1Q26 = 1.297,5 mb = CROLLO di -248 mb in un trimestre
A39: • OECD onland commercial: -30,6 mb (da 2.826,6 a 2.796,0) — molto più contenuto
A41: → COSA SIGNIFICA: il petrolio si è spostato DALL'ACQUA alla TERRA + è stato consumato.
A42: Durante la crisi Hormuz, le navi hanno scaricato (oil-on-water -248mb) ma l'onland NON è salito
A43: proporzionalmente (-30mb) → il delta (~218 mb) è stato CONSUMATO/drenato dal mercato.
A45: Questo CONFERMA il drawdown fisico reale anche con scorte aggregate apparentemente alte:
A46: le scorte 'utilizzabili' calano, mentre l'oil-on-water (Iran dark fleet) era il buffer che si è svuotato.
A48: • Collega SHIP Act + OPEC: la dark fleet iraniana (~280 navi) trasportava parte di quell'oil-on-water.
A49: • Con Hormuz semi-bloccato, quelle navi hanno scaricato in Cina (99% destinazione) → -248mb on water.
A51: 🎯 TESI CONSOLIDATA: scorte aggregate alte (Salhajji) + oil-on-water in crollo (OPEC) + dipendenza
...

Sheet Chokepoints
A1: CHOKEPOINTS MARITTIMI — Hormuz · Bab el-Mandeb · Suez · Malacca (22 luglio 2026)
A2: Il conflitto si è esteso da UNO a TRE punti di strozzatura: il rischio non è più concentrato ma sistemico
A4: Chokepoint | B4: Flusso normale (mbd) | C4: Flusso attuale (mbd) | D4: % vs normale | E4: Stato | F4: Attore | G4: Deviazione alternativa | H4: Extra giorni | I4: Impatto prezzo | J4: Watch | K4: Note
A5: Hormuz | B5: 21.6 | C5: 2 | D5: =C5/B5 -> 0.092592593 | E5: CROLLO transiti | F5: Iran/IRGC | G5: Nessuna (pipeline limitate) | H5: — | I5: ALTISSIMO | J5: ⛔ | K5: CROLLO: transiti commerciali a una cifra fra il 4 e il 9 settembre (da 4 a 7 al giorno), media mobile 10 giorni in calo. Uscite LNG quasi azzerate. Iran annuncia una 'exclusion zone' fuori dallo stretto. Record del 31/8 (17 mbd) già rientrato
A6: Bab el-Mandeb | B6: 5.4 | C6: 6.5 | D6: =C6/B6 -> 1.2037037 | E6: SOTTO ATTACCO | F6: Houthi/Yemen | G6: Capo di Buona Speranza | H6: +21-30 | I6: ALTO | J6: ⛔ | K6: Gli Houthi sono avanzati fino all'isola di Perim, che controlla l'imbocco dello stretto. L'Arabia Saudita ha CHIUSO la pipeline East-West dopo ripetuti attacchi: salta la valvola su Yanbu. Produzione saudita −1,9 mbd ad agosto
A7: Suez / SUMED | B7: 4.9 | C7: 3.2 | D7: =C7/B7 -> 0.65306122 | E7: Congestione | F7: (indiretto) | G7: Capo di Buona Speranza | H7: +21-30 | I7: MEDIO | J7: ⚠ | K7: Alternativa a BAM per cargo da Yanbu: Yanbu→Corea passa da 24 a ~54 giorni via Suez
A8: Malacca | B8: 16 | C8: 15 | D8: =C8/B8 -> 0.9375 | E8: Operativo | F8: — | G8: Lombok/Sunda | H8: +3-5 | I8: BASSO | J8: ✓ | K8: Non direttamente colpito, ma è il collo di bottiglia a valle: tutto ciò che sopravvive a Hormuz/BAM vi transita
A10: TOTALE FLUSSO A RISCHIO | D10: =SUM(B5:B6)-SUM(C5:C6) -> 18.5 | E10: Entrambe le valvole compromesse insieme: Hormuz a transiti da una cifra e Yanbu fermo per chiusura precauzionale della pipeline East-West. Noli delle petroliere ai massimi storici
A12: 🎯 L'ESCALATION GEOGRAFICA — Perché questo cambia il framework
A13: Fino a giugno il modello aveva UN solo chokepoint critico (Hormuz). Da metà luglio ne ha TRE interconnessi:
A15: 1. HORMUZ — chiuso di fatto da febbraio; riaperto col MOU (18/6), richiuso con l'escalation di luglio.
A16: 11° giorno consecutivo di attacchi USA contro l'Iran (22/7) per ridurre la capacità di minaccia al transito.
A18: 2. BAB EL-MANDEB — gli Houthi hanno dichiarato l'embargo navale sull'Arabia Saudita (20/7).
A19: Loadings -36% in due settimane (Kpler). Nessuna petroliera avvistata in transito dopo l'email agli armatori.
A20: CRITICO: Yanbu era la valvola di sfogo che permetteva a Riad di bypassare Hormuz via pipeline.
A21: Export da Yanbu erano saliti a 3.5 mbd in giugno (vs 240 kbd anno prima) — ora a rischio.
A23: 3. SUEZ — unica rotta che evita sia Hormuz sia BAM, ma con costo temporale proibitivo:
A24: Yanbu→Corea del Sud passa da ~24 a ~54 giorni. Il Capo di Buona Speranza aggiunge 21-30 giorni.
A26: 4. MALACCA — non colpito direttamente, ma è il collo di bottiglia a valle per l'Asia.
A27: Va monitorato come indicatore di 'quanto arriva davvero' dopo i due filtri a monte.
... A34: Fonti: EIA (flussi storici) · Kpler (loadings, deviazioni) · JMIC/EU Aspides (advisory) · Clarksons · CFR · Al Jazeera/CNBC/Reuters (22 luglio 2026)

Sheet Europe Energy
A1: EUROPE ENERGY — La Calma Inaspettata
A2: TESI: Nonostante lo shock petrolifero, i mercati elettrici europei sono calmi — divergenza notevole vs crisi 2022
A4: Mese | B4: TTF Gas (€/MWh) | C4: Power Baseload (€/MWh) | D4: Storage % | E4: Solar Gen. (TWh) | F4: Diesel Crack ($/bbl) | G4: Power Bills Proxy (€/MWh) | H4: Calm Index
A5: Gen '25 | B5: 32 | C5: 65 | D5: 0.78 | E5: 8 | F5: 18 | G5: =B5*0.6+C5*0.4 -> 45.2 | H5: =IF(G5<100,"✓ CALMO",IF(G5<200,"⚠ Stress","⛔ Crisi")) -> ✓ CALMO
A6: Apr '25 | B6: 28 | C6: 55 | D6: 0.72 | E6: 18 | F6: 20 | G6: =B6*0.6+C6*0.4 -> 38.8 | H6: =IF(G6<100,"✓ CALMO",IF(G6<200,"⚠ Stress","⛔ Crisi")) -> ✓ CALMO
A7: Lug '25 | B7: 30 | C7: 70 | D7: 0.55 | E7: 30 | F7: 22 | G7: =B7*0.6+C7*0.4 -> 46 | H7: =IF(G7<100,"✓ CALMO",IF(G7<200,"⚠ Stress","⛔ Crisi")) -> ✓ CALMO
A8: Ott '25 | B8: 35 | C8: 80 | D8: 0.85 | E8: 12 | F8: 23 | G8: =B8*0.6+C8*0.4 -> 53 | H8: =IF(G8<100,"✓ CALMO",IF(G8<200,"⚠ Stress","⛔ Crisi")) -> ✓ CALMO
A9: Gen '26 | B9: 38 | C9: 95 | D9: 0.62 | E9: 9 | F9: 25 | G9: =B9*0.6+C9*0.4 -> 60.8 | H9: =IF(G9<100,"✓ CALMO",IF(G9<200,"⚠ Stress","⛔ Crisi")) -> ✓ CALMO
A10: Feb '26 | B10: 40 | C10: 100 | D10: 0.55 | E10: 12 | F10: 26 | G10: =B10*0.6+C10*0.4 -> 64 | H10: =IF(G10<100,"✓ CALMO",IF(G10<200,"⚠ Stress","⛔ Crisi")) -> ✓ CALMO
A11: Mar '26 | B11: 44 | C11: 105 | D11: 0.5 | E11: 22 | F11: 32 | G11: =B11*0.6+C11*0.4 -> 68.4 | H11: =IF(G11<100,"✓ CALMO",IF(G11<200,"⚠ Stress","⛔ Crisi")) -> ✓ CALMO
A12: Apr '26 | B12: 48 | C12: 110 | D12: 0.55 | E12: 32 | F12: 38 | G12: =B12*0.6+C12*0.4 -> 72.8 | H12: =IF(G12<100,"✓ CALMO",IF(G12<200,"⚠ Stress","⛔ Crisi")) -> ✓ CALMO
A13: Mag '26 | B13: 46 | C13: 70 | D13: 0.33 | E13: 38 | F13: 45 | G13: =B13*0.6+C13*0.4 -> 55.6 | H13: =IF(G13<100,"✓ CALMO",IF(G13<200,"⚠ Stress","⛔ Crisi")) -> ✓ CALMO
A14: Mag-S2 '26 | B14: 50 | C14: 75 | D14: 0.36 | E14: 40 | F14: 50 | G14: =B14*0.6+C14*0.4 -> 60 | H14: =IF(G14<100,"✓ CALMO",IF(G14<200,"⚠ Stress","⛔ Crisi")) -> ✓ CALMO
A15: Mag-S3 '26 | B15: 42 | C15: 68 | D15: 0.38 | E15: 42 | F15: 42 | G15: =B15*0.6+C15*0.4 -> 52.4 | H15: =IF(G15<100,"✓ CALMO",IF(G15<200,"⚠ Stress","⛔ Crisi")) -> ✓ CALMO
A16: Giu-S1 '26
A17: Lug-S1 '26 | B17: 33 | C17: 58 | D17: 0.55 | E17: 48 | F17: 28 | G17: =B17*0.6+C17*0.4 -> 43 | H17: =IF(G17<100,"✓ CALMO",IF(G17<200,"⚠ Stress","⛔ Crisi")) -> ✓ CALMO
A18: Lug-S3 '26 | B18: 52 | C18: 110 | D18: 0.537 | E18: 46 | F18: 55 | G18: =B18*0.6+C18*0.4 -> 75.2 | H18: =IF(OR(G18>=100,D18<0.7),"⛔ CRISI",IF(OR(G18>=80,D18<0.8),"⚠ STRESS","✓ CALMO")) -> ⛔ CRISI
A19: Ago-S2 '26 | B19: 62 | C19: 125 | D19: 0.59 | E19: 45 | F19: 78 | G19: =B19*0.6+C19*0.4 -> 87.2 | H19: =IF(OR(G19>=100,D19<0.7),"⛔ CRISI",IF(OR(G19>=80,D19<0.8),"⚠ STRESS","✓ CALMO")) -> ⛔ CRISI
A20: Ago-S4 '26 | B20: 66 | C20: 130 | D20: 0.63 | E20: 40 | F20: 78 | G20: =B20*0.6+C20*0.4 -> 91.6 | H20: =IF(OR(G20>=100,D20<0.7),"⛔ CRISI",IF(OR(G20>=80,D20<0.8),"⚠ STRESS","✓ CALMO")) -> ⛔ CRISI
A21: Set-S1 '26 | B21: 72 | C21: 135 | D21: 0.654 | E21: 35 | F21: 74 | G21: =B21*0.6+C21*0.4 -> 97.2 | H21: =IF(OR(G21>=100,D21<0.7),"⛔ CRISI",IF(OR(G21>=80,D21<0.8),"⚠ STRESS","✓ CALMO")) -> ⛔ CRISI
A22: Set-S2 '26 | B22: 80 | C22: 150 | D22: 0.67 | E22: 30 | F22: 80 | G22: =B22*0.6+C22*0.4 -> 108 | H22: =IF(OR(G22>=100,D22<0.7),"⛔ CRISI",IF(OR(G22>=80,D22<0.8),"⚠ STRESS","✓ CALMO")) -> ⛔ CRISI
A23: Picco 2022
A24: NOTE & FONTI
A26: • Col 'TTF Gas (€/MWh)' (input): Dutch TTF natural gas front-month — proxy energia europea
A27: • Col 'Power Baseload (€/MWh)' (input): DE/FR/IT baseload electricity average
A28: • Col 'Storage %' (input): Gas storage levels EU-27 — GIE/AGSI
A29: • Col 'Solar Gen. (TWh)' (input): Generazione solare UE mensile
A30: • Col 'Diesel Crack ($/bbl)' (input): Diesel-Brent crack spread — Europa è net importer
A31: • Col 'Power Bills Proxy (€/MWh)' (formula): Proxy bolletta = TTF×0.6 + Power baseload×0.4 (mix sintetico)
A32: • Col 'Calm Index' (formula): Compositore: bollette vs picco 2022 (€350/MWh)
A34: ⚠ CORREZIONE 6/9 — TTF e stoccaggi rettificati su dati verificati. TTF €72/MWh il 4/9: massimo da oltre tre anni, +7% settimanale, quarta settimana consecutiva di rialzo (le stime precedenti, €44-46, erano errate).
A35: Stoccaggi UE da GIE AGSI+: 53,7% (20/7) · 61,8% (20/8) · 63% (27/8) · 65,4% (1/9). Sono 16,6 punti sotto la media quinquennale e il livello più basso per la data dal 2011. Il target UE è stato allentato da 90% a 80% al 1° novembre.
A36: Causa: circa un quinto del commercio LNG mondiale passa da Hormuz, quasi tutto qatarino. Import mediorientali ai minimi dal 2019; ritorno non atteso prima del Q4 per i tempi di sminamento.
... A38: Soglia di stato ricalibrata: crisi se il proxy supera 100 OPPURE se lo stoccaggio scende sotto il 70%. Con scorte al minimo storico un prezzo 'medio' non significa calma.

Sheet Crack & Pompa IT
A1: CRACK SPREAD & PREZZI ALLA POMPA ITALIA — 11 settembre 2026
A2: Lo shock si è spostato dal greggio ai prodotti: il Brent scende, i carburanti no. Scomposizione del prezzo finale
A4: 🔥 CRACK SPREAD DIESEL — I tre hub di raffinazione
A5: Hub / benchmark | B5: Norma storica | C5: Attuale (fine ago) | D5: Picco agosto | E5: vs norma | F5: Note
A6: US Gulf Coast ULSD vs WTI | B6: 30 | C6: 102 | D6: 102 | E6: =C6/B6 -> 3.4 | F6: Diesel USA oltre $6 al gallone: primo record assoluto
A7: NW Europe ICE gasoil vs Brent | B7: 28 | C7: 88 | D7: 95 | E7: =C7/B7 -> 3.1428571 | F7: È il riferimento per il gasolio italiano
A8: Singapore gasoil vs Dubai | B8: 25 | C8: 80 | D8: — | E8: =C8/B8 -> 3.2 | F8: Anche l'Asia è tesa: nessun arbitraggio di sollievo
A10: ⛽ SCOMPOSIZIONE DEL PREZZO ALLA POMPA (self, rete stradale, €/litro)
A11: Componente | B11: Benzina | C11: Gasolio | D11: Gasolio senza sconto | E11: Δ Gasolio-Benzina | F11: Commento
A12: Costo greggio (Brent) | B12: 0.562 | C12: 0.562 | D12: 0.562 | E12: =C12-B12 -> 0 | F12: Brent $104,6/bbl: identico per entrambi
A13: Crack + logistica + margine | B13: 0.475 | C13: 0.703 | D13: 0.703 | E13: =C13-B13 -> 0.228 | F13: Crack e margine: la differenza vale 23 centesimi
A14: Accisa | B14: 0.6729 | C14: 0.5329 | D14: 0.6729 | E14: =C14-B14 -> -0.14 | F14: Accisa allineata a 0,6729 €/l dal 1/1/2026; gasolio ridotto a 0,5329
A15: IVA 22% | B15: 0.3762 | C15: 0.3955 | D15: 0.4263 | E15: =C15-B15 -> 0.0193 | F15: IVA 22%, applicata anche sull'accisa
A16: PREZZO FINALE | B16: =SUM(B12:B15) -> 2.0861 | C16: =SUM(C12:C15) -> 2.1934 | D16: =SUM(D12:D15) -> 2.3642 | E16: =C16-B16 -> 0.1073 | F16: Mimit 11/9: benzina 2,086 · gasolio 2,193 (self, rete stradale). Benzina al massimo da giugno 2022
A17: di cui imposte (accisa+IVA) | B17: =(B14+B15)/B16 -> 0.50290015 | C17: =(C14+C15)/C16 -> 0.42326981 | D17: =(D14+D15)/D16 -> 0.46493528 | F17: CORREZIONE: l'accisa benzina non è 0,821 ma 0,6729, pari a quella del gasolio dopo il riallineamento del 1/1/2026
A19: 🔍 PERCHÉ I PRODOTTI SCARSEGGIANO — Le cinque fratture simultanee
A20: 1. HORMUZ — le raffinerie mediorientali esportavano distillati verso Europa e Asia. Con lo stretto a un quarto della portata, quel flusso si è fermato. Attacco Houthi alla raffineria saudita di Jazan.
A21: 2. RUSSIA — i droni ucraini hanno colpito ripetutamente le raffinerie russe; Mosca ha risposto vietando l'export di diesel. Fuori dal mercato un volume rilevante del pool globale.
A22: 3. CINA — Pechino non ha riattivato l'export di prodotti raffinati, per timore di carenze interne. Quello che raffina resta in casa: nessun sollievo dall'Asia.
A23: 4. STATI UNITI — restano l'unico hub pienamente operativo, e l'Europa ne assorbe volumi record. Ma questo prosciuga le scorte USA: distillati a 107,1 mb, minimo per il periodo dal 1996.
A24: 5. SPR — i rilasci strategici calmierano il GREGGIO, non i prodotti. Si svuota la riserva (sotto 300 mb) senza risolvere il collo di bottiglia, che è a valle nella raffinazione.
A26: 💡 L'INSIGHT — Lo shock si è spostato a valle
A27: Il Brent è sceso da $105 (23 luglio) a ~$87, eppure benzina e gasolio in Italia sono ai massimi dal 2022. Non è una contraddizione:
A29: • Il greggio è caro ma DISPONIBILE — i rilasci SPR e la domanda cinese ridotta lo tengono sotto controllo
A30: • I prodotti raffinati sono SCARSI — tre dei quattro hub di raffinazione mondiali sono compromessi contemporaneamente
A31: • Il crack gasoil europeo a $78 (picco $95) contro una norma di $25-30 vale da solo circa 0,35 €/litro in più alla pompa
A33: → Il collo di bottiglia non è più l'estrazione, è la RAFFINAZIONE. Per questo i rilasci strategici di greggio non funzionano:
... A39: Fonti: Mimit (prezzi 27/8) · ICE/OPIS/Sparta (crack) · EIA (distillati USA) · Goldman, Citi, BofA, Jefferies (note clienti) · Ansa/Quattroruote (accise). Scomposizione: elaborazione propria su accisa gasolio 617,4 €/1000l ridotta di 0,140 e benzina 728,4 €/1000l, IVA 22%, cambio ~1,17.

Sheet Global Inventories
A1: GLOBAL CRUDE INVENTORIES — Replicazione EOA/Salhajji (27 maggio 2026)
A2: Inventari commerciali globali 2024 vs 2025 vs 2026 — il dato che ricalibra lo scenario shock
A4: 📊 SCORTE ATTUALI (W22) | C4: VS 2025 | E4: VS 2024 | G4: SCENARIO SHOCK?
A5: 2.43 Bn bbl | C5: +0.08 (+3.4%) | E5: +0.12 (+5.2%) | G5: ⚠ CONFUTATO
A8: Settimana | B8: 2024 | C8: 2025 | D8: 2026 | E8: 2026 vs 2025 | F8: 2026 vs 2024 | G8: Δ Verso 2026 | H8: Note
A9: W1 | B9: 2.28 | C9: 2.26 | D9: 2.4 | E9: =D9-C9 -> 0.14 | F9: =D9-B9 -> 0.12 | H9: Inizio anno: 2026 entra ALTO (build Q4-25)
A10: W3 | B10: 2.27 | C10: 2.26 | D10: 2.42 | E10: =D10-C10 -> 0.16 | F10: =D10-B10 -> 0.15 | G10: =D10-D9 -> 0.02
A11: W5 | B11: 2.26 | C11: 2.28 | D11: 2.43 | E11: =D11-C11 -> 0.15 | F11: =D11-B11 -> 0.17 | G11: =D11-D10 -> 0.01 | H11: Build continua nonostante incertezza Hormuz
A12: W7 | B12: 2.25 | C12: 2.28 | D12: 2.44 | E12: =D12-C12 -> 0.16 | F12: =D12-B12 -> 0.19 | G12: =D12-D11 -> 0.01
A13: W9 | B13: 2.25 | C13: 2.3 | D13: 2.45 | E13: =D13-C13 -> 0.15 | F13: =D13-B13 -> 0.2 | G13: =D13-D12 -> 0.01
A14: W11 | B14: 2.27 | C14: 2.3 | D14: 2.46 | E14: =D14-C14 -> 0.16 | F14: =D14-B14 -> 0.19 | G14: =D14-D13 -> 0.01
A15: W13 | B15: 2.28 | C15: 2.32 | D15: 2.47 | E15: =D15-C15 -> 0.15 | F15: =D15-B15 -> 0.19 | G15: =D15-D14 -> 0.01
A16: W15 | B16: 2.29 | C16: 2.32 | D16: 2.46 | E16: =D16-C16 -> 0.14 | F16: =D16-B16 -> 0.17 | G16: =D16-D15 -> -0.01
A17: W17 | B17: 2.3 | C17: 2.33 | D17: 2.45 | E17: =D17-C17 -> 0.12 | F17: =D17-B17 -> 0.15 | G17: =D17-D16 -> -0.01 | H17: Inizio crisi Hormuz (~W9)
A18: W19 | B18: 2.3 | C18: 2.34 | D18: 2.44 | E18: =D18-C18 -> 0.1 | F18: =D18-B18 -> 0.14 | G18: =D18-D17 -> -0.01
A19: W21 | B19: 2.31 | C19: 2.34 | D19: 2.43 | E19: =D19-C19 -> 0.09 | F19: =D19-B19 -> 0.12 | G19: =D19-D18 -> -0.01 | H19: Peak inventory 2026 — pre-drawdown
A20: W23 | B20: 2.32 | C20: 2.35 | D20: 2.43 | E20: =D20-C20 -> 0.08 | F20: =D20-B20 -> 0.11 | G20: =D20-D19 -> 0
A21: W25 | B21: 2.32 | C21: 2.35
A22: W27 | B22: 2.31 | C22: 2.34
A23: W29 | B23: 2.3 | C23: 2.34 | H23: Drawdown inizia — IEA OMR conferma
A24: W31 | B24: 2.3 | C24: 2.33
A25: W33 | B25: 2.3 | C25: 2.33 | H25: Drawdown -129 mb (marzo)
A26: W35 | B26: 2.29 | C26: 2.33
A27: W37 | B27: 2.29 | C27: 2.34 | H27: Drawdown -117 mb (aprile) + floating +53
A28: W39 | B28: 2.28 | C28: 2.35
A29: W41 | B29: 2.28 | C29: 2.36 | H29: Stabilizzazione attorno a 2.43
A30: W43 | B30: 2.29 | C30: 2.38
A31: W45 | B31: 2.29 | C31: 2.4 | H31: Settimana attuale W22-W23
A32: W47 | B32: 2.3 | C32: 2.41
A33: W49 | B33: 2.3 | C33: 2.42
A34: W51 | B34: 2.31 | C34: 2.42
A37: 🔍 ANALISI INTEGRATA — Perché il dato è importante e cosa ricalibra
A39: 1. PERCHÉ LE SCORTE RESTANO ALTE NONOSTANTE LA GUERRA
A40: • ENTRATA ANNO ALTA: 2026 ha iniziato con scorte già ai massimi del periodo (build Q4-25 +2.3 mbd per EIA STEO Set-25)
A41: • ATLANTIC BASIN SURGE: USA + Brazil + Canada + Kazakhstan + Venezuela hanno aumentato export di +3.5 mbd (IEA OMR May)
A42: • CHINA DEMAND DESTRUCTION: -3.6 mbd seaborne imports = -3.6 mbd di consumo NON realizzato
A43: • FLOATING STORAGE BOOM: +53 mbbls in aprile (IEA) — petrolio fisico esiste, è solo parcheggiato in mare
A44: • IEA COORDINATED RELEASE: 400 mbbls SPR globali in rilascio (USA 172 mbbls) — aggiunge ulteriore supply
A45: • NET RESULT: scorte commerciali Kpler restano sopra 2025, MA distribuzione molto diversa (più floating, meno on-land)
A47: 2. COSA RICALIBRA NEL FRAMEWORK BLAS
...

Sheet Brent Scenarios
A1: BRENT PRICE SCENARIOS — Ricalibrato post-dato scorte (28 maggio 2026)
A2: Scenari probabilistici aggiornati per integrare scorte globali alte (no scarcity fisica acuta nel breve)
A4: BRENT SPOT | C4: EXPECTED Q3 '26 | E4: RANGE Q3 '26 | G4: VS PRECEDENTE | I4: VOLATILITÀ
A5: $104.6 | C5: =J14 -> 119.54 | E5: $95–130 | G5: ↑ da $88–115 | I5: ALTA (range $40+)
A7: 📊 SCENARI PROBABILISTICI — 5 percorsi con price target e driver
A8: Scenario | B8: Prob. | C8: Brent Q3 (target) | D8: Brent range | E8: Driver primario | F8: Trigger | G8: Tesi Blas impatto | H8: Scorte effetto | I8: Timing | J8: P×Target
A9: A. De-escalation (cease-fire) | B9: 0.18 | C9: 88 | D9: $82–95 | E9: Accordo temporaneo GCC-Iran sulla gestione dei transiti | F9: Vertice in Oman lunedì 14/9 | G9: T4 confermata | H9: Collasso rapido | I9: Q3-Q4 '26 | J9: =B9*C9 -> 15.84
A10: B. Stallo gestito (BASE CASE) | B10: 0.32 | C10: 105 | D10: $98–115 | E10: Guerra dei noli: transiti bassi, premio rischio stabile | F10: STATUS QUO (11/9) | G10: Tutte 4 reggono | H10: Drawdown lento | I10: Q3 '26 | J10: =B10*C10 -> 33.6
A11: C. Logoramento (grinding) | B11: 0.28 | C11: 125 | D11: $118–135 | E11: Exclusion zone attuata + Yanbu fermo a lungo | F11: Iran annuncia zona di esclusione; pipeline saudita chiusa | G11: T2/T3 stress | H11: On-land critico | I11: Q4 '26 | J11: =B11*C11 -> 35
A12: D. Shock acuto (escalation) | B12: 0.16 | C12: 150 | D12: $140–165 | E12: Guerra lunga: Goldman vede >$120 se il Golfo resta −4 mbd | F12: Funzionari USA: il conflitto può durare fino al 2029 | G12: T3 rotta | H12: Scarcity reale | I12: Improvviso | J12: =B12*C12 -> 24
A13: E. Tail risk (crisi sistemica) | B13: 0.06 | C13: 185 | D13: $170–210 | E13: Allargamento pieno al Golfo | F13: Houthi a Perim; attacchi a impianti sauditi | G13: Framework rotto | H13: Panico totale | I13: Improvviso | J13: =B13*C13 -> 11.1
A14: EXPECTED VALUE | B14: =SUM(B9:B13) -> 1 | C14: Prezzo atteso ponderato per probabilità (somma P×Target) → | J14: =SUM(J9:J13) -> 119.54
A17: 🔄 LOGICA DI RICALIBRAZIONE — Cosa è cambiato e perché
A19: PARAMETRO | D19: PRIMA | F19: DOPO | H19: RAGIONE
A20: Range Q3 '26 | D20: $105–130 | F20: $95–115 | H20: Scorte alte = no scarcity acuta
A21: Expected value | D21: ~$118 | F21: ~$112 (modale $105) | H21: Shift probabilità verso scenari moderati
A22: Prob. shock acuto (D+E) | D22: ~25% | F22: ~15% | H22: Scorte aggregate alte riducono tail risk breve
A23: Prob. base case (B) | D23: ~30% | F23: ~40% | H23: Stallo gestito più probabile con buffer scorte
A24: Prob. de-escalation (A) | D24: ~20% | F24: ~25% | H24: Downside più pronunciato se cease-fire
A25: Timing stress acuto | D25: Ago-Set '26 | F25: Q4'26 / Q1'27 | H25: Buffer scorte posticipa il punto critico
A28: ⚖ L'ASIMMETRIA CHIAVE — Downside vs Upside
A29: Il dato scorte introduce un'ASIMMETRIA importante nel profilo rischio/rendimento di Brent:
A31: 📉 DOWNSIDE (se cease-fire): collasso RAPIDO e PROFONDO
A32: • Scorte alte + ritorno flussi Hormuz + demand cinese parz. recuperata = oversupply immediato
A33: • Brent può crollare a $75-85 in poche settimane (scenario A)
A34: • Le scorte alte AMPLIFICANO il downside, non lo attenuano
A36: 📈 UPSIDE (se escalation): più LENTO ad arrivare ma più VIOLENTO
A37: • Le scorte alte fanno da cuscinetto iniziale → primo mese assorbe lo shock
A38: • Ma se on-land drawdown continua a -5.7 mbpd, il buffer si esaurisce in ~3-4 mesi
A39: • Oltre quel punto: salto a $140-180 (scenario D) perché floating storage NON è fungibile
A41: 🎯 IMPLICAZIONE STRATEGICA:
A42: • Nel BREVE (1-3 mesi): bias ribassista — scorte alte dominano, Brent verso $95-105
... A52: • Aggiornare le probabilità ad ogni 'aggiorna' settimanale in base ai nuovi datapoint.

Sheet Update Calendar
A1: CALENDARIO UPDATE — CHECKLIST FONTI & FREQUENZE
A2: Tutte le fonti da consultare per mantenere il tracker aggiornato — barrare quando consultate
A4: SETTIMANA CORRENTE | D4: COMPLETION % | G4: ULTIMO UPDATE
A5: 11 May → 17 May 2026 | D5: =COUNTIF(G9:G35,"✓")&" / "&COUNTA(G9:G35) -> 0 / 0 | G5: 2026-05-14 08:16
A7: ✓ | B7: Tesi | C7: Fonte | D7: Indicatore | E7: Freq. | F7: Giorno Pub. | G7: Done | H7: Last Date | I7: Last Value | J7: Link | K7: Note
A8: 🔴 SETTIMANALI — Da consultare ogni settimana
A9: ☐ | B9: T2 | C9: EIA Weekly Petroleum Status | D9: Crude/gasoline stocks, production, refinery util, exports | E9: Settim. | F9: Mercoledì | J9: Apri → | K9: Pubblicato alle 16:30 UTC. Il dato più importante per Tesi 2
A10: ☐ | B10: T1 | C10: Kpler China Crude Imports | D10: Daily AIS-based China crude import flows | E10: Settim. | F10: Giovedì | J10: Apri → | K10: Subscription. Vortexa è alternativa simile
A11: ☐ | B11: T1+T4 | C11: Vortexa AIS Tracking | D11: Iran exports, Hormuz transit count, dark fleet | E11: Settim. | F11: Continuo | J11: Apri → | K11: Subscription. Bloomberg dispone di feed parziale
