Workbook

Sheet Leggimi
A1: Inflazione area euro - storico e foglio di aggiornamento
A2: Ultimo dato: 2026-09
A4: Fogli EA, IT, DE, FR, ES: indici di fonte (blu) e trasformazioni (formule, nero):
A5: base gennaio 2020 = 100, variazione mensile, annua, 3m/3m annualizzato su serie destagionalizzata.
A6: Indice SA in blu = pubblicato dalla BCE; in nero = destagionalizzazione interna (STL).
A7: Riepilogo e Potere acquisto: formule che leggono i fogli area (verde).
A8: Proiezioni, Distribuzione, Sottostanti, Salari, Voci: calcoli del motore (valori).
A10: Per correggere o aggiungere un dato: scrivilo nella colonna 'Indice fonte' del foglio area;
A11: le formule della riga e il Riepilogo si aggiornano da soli.

Sheet Riepilogo
A1: Riepilogo - ultimo dato 2026-09
A2: Formule collegate ai fogli area: si aggiornano con i dati.
A4: Area | B4: Misura | C4: Mese | D4: Indice gen20=100 | E4: m/m | F4: a/a | G4: 3m/3m ann.
A5: Area euro | B5: HICP generale | C5: ='EA'!A145 | D5: ='EA'!C145 | E5: ='EA'!D145 | F5: ='EA'!E145 | G5: ='EA'!G145
A6: Area euro | B6: Core (escl. energia, alimentari, alcol e tabacchi) | C6: ='EA'!A145 | D6: ='EA'!I145 | E6: ='EA'!J145 | F6: ='EA'!K145 | G6: ='EA'!M145
A7: Area euro | B7: Al netto degli energetici | C7: ='EA'!A145 | D7: ='EA'!O145 | E7: ='EA'!P145 | F7: ='EA'!Q145 | G7: ='EA'!S145
A8: Area euro | B8: Beni | C8: ='EA'!A145 | D8: ='EA'!U145 | E8: ='EA'!V145 | F8: ='EA'!W145 | G8: ='EA'!Y145
A9: Area euro | B9: Servizi | C9: ='EA'!A145 | D9: ='EA'!AA145 | E9: ='EA'!AB145 | F9: ='EA'!AC145 | G9: ='EA'!AE145
A10: Area euro | B10: Alimentari (incl. alcol e tabacchi) | C10: ='EA'!A145 | D10: ='EA'!AG145 | E10: ='EA'!AH145 | F10: ='EA'!AI145 | G10: ='EA'!AK145
A11: Area euro | B11: Energia | C11: ='EA'!A145 | D11: ='EA'!AM145 | E11: ='EA'!AN145 | F11: ='EA'!AO145 | G11: ='EA'!AQ145
A12: Area euro | B12: Trasporti | C12: ='EA'!A145 | D12: ='EA'!AS145 | E12: ='EA'!AT145 | F12: ='EA'!AU145 | G12: ='EA'!AW145
A13: Italia | B13: HICP generale | C13: ='IT'!A145 | D13: ='IT'!C145 | E13: ='IT'!D145 | F13: ='IT'!E145 | G13: ='IT'!G145
A14: Italia | B14: Core (escl. energia, alimentari, alcol e tabacchi) | C14: ='IT'!A145 | D14: ='IT'!I145 | E14: ='IT'!J145 | F14: ='IT'!K145 | G14: ='IT'!M145
A15: Italia | B15: Al netto degli energetici | C15: ='IT'!A145 | D15: ='IT'!O145 | E15: ='IT'!P145 | F15: ='IT'!Q145 | G15: ='IT'!S145
A16: Italia | B16: Beni | C16: ='IT'!A145 | D16: ='IT'!U145 | E16: ='IT'!V145 | F16: ='IT'!W145 | G16: ='IT'!Y145
A17: Italia | B17: Servizi | C17: ='IT'!A145 | D17: ='IT'!AA145 | E17: ='IT'!AB145 | F17: ='IT'!AC145 | G17: ='IT'!AE145
A18: Italia | B18: Alimentari (incl. alcol e tabacchi) | C18: ='IT'!A145 | D18: ='IT'!AG145 | E18: ='IT'!AH145 | F18: ='IT'!AI145 | G18: ='IT'!AK145
A19: Italia | B19: Energia | C19: ='IT'!A145 | D19: ='IT'!AM145 | E19: ='IT'!AN145 | F19: ='IT'!AO145 | G19: ='IT'!AQ145
A20: Italia | B20: Trasporti | C20: ='IT'!A145 | D20: ='IT'!AS145 | E20: ='IT'!AT145 | F20: ='IT'!AU145 | G20: ='IT'!AW145
A21: Germania | B21: HICP generale | C21: ='DE'!A145 | D21: ='DE'!C145 | E21: ='DE'!D145 | F21: ='DE'!E145 | G21: ='DE'!G145
A22: Germania | B22: Core (escl. energia, alimentari, alcol e tabacchi) | C22: ='DE'!A145 | D22: ='DE'!I145 | E22: ='DE'!J145 | F22: ='DE'!K145 | G22: ='DE'!M145
A23: Germania | B23: Al netto degli energetici | C23: ='DE'!A145 | D23: ='DE'!O145 | E23: ='DE'!P145 | F23: ='DE'!Q145 | G23: ='DE'!S145
A24: Germania | B24: Beni | C24: ='DE'!A145 | D24: ='DE'!U145 | E24: ='DE'!V145 | F24: ='DE'!W145 | G24: ='DE'!Y145
A25: Germania | B25: Servizi | C25: ='DE'!A145 | D25: ='DE'!AA145 | E25: ='DE'!AB145 | F25: ='DE'!AC145 | G25: ='DE'!AE145
A26: Germania | B26: Alimentari (incl. alcol e tabacchi) | C26: ='DE'!A145 | D26: ='DE'!AG145 | E26: ='DE'!AH145 | F26: ='DE'!AI145 | G26: ='DE'!AK145
A27: Germania | B27: Energia | C27: ='DE'!A145 | D27: ='DE'!AM145 | E27: ='DE'!AN145 | F27: ='DE'!AO145 | G27: ='DE'!AQ145
A28: Germania | B28: Trasporti | C28: ='DE'!A145 | D28: ='DE'!AS145 | E28: ='DE'!AT145 | F28: ='DE'!AU145 | G28: ='DE'!AW145
A29: Francia | B29: HICP generale | C29: ='FR'!A145 | D29: ='FR'!C145 | E29: ='FR'!D145 | F29: ='FR'!E145 | G29: ='FR'!G145
A30: Francia | B30: Core (escl. energia, alimentari, alcol e tabacchi) | C30: ='FR'!A145 | D30: ='FR'!I145 | E30: ='FR'!J145 | F30: ='FR'!K145 | G30: ='FR'!M145
A31: Francia | B31: Al netto degli energetici | C31: ='FR'!A145 | D31: ='FR'!O145 | E31: ='FR'!P145 | F31: ='FR'!Q145 | G31: ='FR'!S145
A32: Francia | B32: Beni | C32: ='FR'!A145 | D32: ='FR'!U145 | E32: ='FR'!V145 | F32: ='FR'!W145 | G32: ='FR'!Y145
A33: Francia | B33: Servizi | C33: ='FR'!A145 | D33: ='FR'!AA145 | E33: ='FR'!AB145 | F33: ='FR'!AC145 | G33: ='FR'!AE145
A34: Francia | B34: Alimentari (incl. alcol e tabacchi) | C34: ='FR'!A145 | D34: ='FR'!AG145 | E34: ='FR'!AH145 | F34: ='FR'!AI145 | G34: ='FR'!AK145
A35: Francia | B35: Energia | C35: ='FR'!A145 | D35: ='FR'!AM145 | E35: ='FR'!AN145 | F35: ='FR'!AO145 | G35: ='FR'!AQ145
A36: Francia | B36: Trasporti | C36: ='FR'!A145 | D36: ='FR'!AS145 | E36: ='FR'!AT145 | F36: ='FR'!AU145 | G36: ='FR'!AW145
A37: Francia | B37: CPI nazionale generale | C37: ='FR'!A145 | D37: ='FR'!AY145 | E37: ='FR'!AZ145 | F37: ='FR'!BA145 | G37: ='FR'!BC145
A38: Spagna | B38: HICP generale | C38: ='ES'!A145 | D38: ='ES'!C145 | E38: ='ES'!D145 | F38: ='ES'!E145 | G38: ='ES'!G145
A39: Spagna | B39: Core (escl. energia, alimentari, alcol e tabacchi) | C39: ='ES'!A145 | D39: ='ES'!I145 | E39: ='ES'!J145 | F39: ='ES'!K145 | G39: ='ES'!M145
A40: Spagna | B40: Al netto degli energetici | C40: ='ES'!A145 | D40: ='ES'!O145 | E40: ='ES'!P145 | F40: ='ES'!Q145 | G40: ='ES'!S145
A41: Spagna | B41: Beni | C41: ='ES'!A145 | D41: ='ES'!U145 | E41: ='ES'!V145 | F41: ='ES'!W145 | G41: ='ES'!Y145
...

Sheet EA
A1: Area euro - indici e variazioni
A2: Blu = dato di fonte; nero = formula. Variazioni in %, 3m/3m su serie destagionalizzata.
B3: HICP generale | H3: Core (escl. energia, alimentari, alcol e tabacchi) | N3: Al netto degli energetici | T3: Beni | Z3: Servizi | AF3: Alimentari (incl. alcol e tabacchi) | AL3: Energia | AR3: Trasporti
A4: Mese | B4: Indice fonte | C4: Base gen20=100 | D4: m/m | E4: a/a | F4: Indice SA | G4: 3m/3m ann. | H4: Indice fonte | I4: Base gen20=100 | J4: m/m | K4: a/a | L4: Indice SA | M4: 3m/3m ann. | N4: Indice fonte | O4: Base gen20=100 | P4: m/m | Q4: a/a | R4: Indice SA | S4: 3m/3m ann. | T4: Indice fonte | U4: Base gen20=100 | V4: m/m | W4: a/a | X4: Indice SA | Y4: 3m/3m ann. | Z4: Indice fonte | AA4: Base gen20=100 | AB4: m/m | AC4: a/a | AD4: Indice SA | AE4: 3m/3m ann. | AF4: Indice fonte | AG4: Base gen20=100 | AH4: m/m | AI4: a/a | AJ4: Indice SA | AK4: 3m/3m ann. | AL4: Indice fonte | AM4: Base gen20=100 | AN4: m/m | AO4: a/a | AP4: Indice SA | AQ4: 3m/3m ann. | AR4: Indice fonte | AS4: Base gen20=100 | AT4: m/m | AU4: a/a | AV4: Indice SA | AW4: 3m/3m ann.
A5: 42005 | B5: 76.3 | C5: =IF(ISNUMBER(B5),B5/B$65*100,"") | F5: 77.18 | H5: 80.2 | I5: =IF(ISNUMBER(H5),H5/H$65*100,"") | L5: 81.57 | N5: 77.7 | O5: =IF(ISNUMBER(N5),N5/N$65*100,"") | R5: 78.7 | T5: 75.65 | U5: =IF(ISNUMBER(T5),T5/T$65*100,"") | X5: 76.54 | Z5: 77.94 | AA5: =IF(ISNUMBER(Z5),Z5/Z$65*100,"") | AD5: 78.77 | AF5: 69.99 | AG5: =IF(ISNUMBER(AF5),AF5/AF$65*100,"") | AJ5: 69.86 | AL5: 67.54 | AM5: =IF(ISNUMBER(AL5),AL5/AL$65*100,"") | AP5: 67.54 | AR5: 76.24 | AS5: =IF(ISNUMBER(AR5),AR5/AR$65*100,"") | AV5: 76.5122
A6: 42036 | B6: 76.78 | C6: =IF(ISNUMBER(B6),B6/B$65*100,"") | D6: =IF(AND(ISNUMBER(B6),ISNUMBER(B5)),B6/B5-1,"") | F6: 77.48 | H6: 80.62 | I6: =IF(ISNUMBER(H6),H6/H$65*100,"") | J6: =IF(AND(ISNUMBER(H6),ISNUMBER(H5)),H6/H5-1,"") | L6: 81.74 | N6: 78.1 | O6: =IF(ISNUMBER(N6),N6/N$65*100,"") | P6: =IF(AND(ISNUMBER(N6),ISNUMBER(N5)),N6/N5-1,"") | R6: 78.9 | T6: 76.12 | U6: =IF(ISNUMBER(T6),T6/T$65*100,"") | V6: =IF(AND(ISNUMBER(T6),ISNUMBER(T5)),T6/T5-1,"") | X6: 76.93 | Z6: 78.41 | AA6: =IF(ISNUMBER(Z6),Z6/Z$65*100,"") | AB6: =IF(AND(ISNUMBER(Z6),ISNUMBER(Z5)),Z6/Z5-1,"") | AD6: 78.96 | AF6: 70.3 | AG6: =IF(ISNUMBER(AF6),AF6/AF$65*100,"") | AH6: =IF(AND(ISNUMBER(AF6),ISNUMBER(AF5)),AF6/AF5-1,"") | AJ6: 70.14 | AL6: 68.6 | AM6: =IF(ISNUMBER(AL6),AL6/AL$65*100,"") | AN6: =IF(AND(ISNUMBER(AL6),ISNUMBER(AL5)),AL6/AL5-1,"") | AP6: 68.6 | AR6: 77.15 | AS6: =IF(ISNUMBER(AR6),AR6/AR$65*100,"") | AT6: =IF(AND(ISNUMBER(AR6),ISNUMBER(AR5)),AR6/AR5-1,"") | AV6: 77.1859
A7: 42064 | B7: 77.67 | C7: =IF(ISNUMBER(B7),B7/B$65*100,"") | D7: =IF(AND(ISNUMBER(B7),ISNUMBER(B6)),B7/B6-1,"") | F7: 77.62 | H7: 81.76 | I7: =IF(ISNUMBER(H7),H7/H$65*100,"") | J7: =IF(AND(ISNUMBER(H7),ISNUMBER(H6)),H7/H6-1,"") | L7: 81.73 | N7: 78.95 | O7: =IF(ISNUMBER(N7),N7/N$65*100,"") | P7: =IF(AND(ISNUMBER(N7),ISNUMBER(N6)),N7/N6-1,"") | R7: 78.89 | T7: 77.64 | U7: =IF(ISNUMBER(T7),T7/T$65*100,"") | V7: =IF(AND(ISNUMBER(T7),ISNUMBER(T6)),T7/T6-1,"") | X7: 77.22 | Z7: 78.5 | AA7: =IF(ISNUMBER(Z7),Z7/Z$65*100,"") | AB7: =IF(AND(ISNUMBER(Z7),ISNUMBER(Z6)),Z7/Z6-1,"") | AD7: 78.89 | AF7: 70.31 | AG7: =IF(ISNUMBER(AF7),AF7/AF$65*100,"") | AH7: =IF(AND(ISNUMBER(AF7),ISNUMBER(AF6)),AF7/AF6-1,"") | AJ7: 70.14 | AL7: 69.79 | AM7: =IF(ISNUMBER(AL7),AL7/AL$65*100,"") | AN7: =IF(AND(ISNUMBER(AL7),ISNUMBER(AL6)),AL7/AL6-1,"") | AP7: 69.79 | AR7: 78.17 | AS7: =IF(ISNUMBER(AR7),AR7/AR$65*100,"") | AT7: =IF(AND(ISNUMBER(AR7),ISNUMBER(AR6)),AR7/AR6-1,"") | AV7: 78.482
A8: 42095 | B8: 78 | C8: =IF(ISNUMBER(B8),B8/B$65*100,"") | D8: =IF(AND(ISNUMBER(B8),ISNUMBER(B7)),B8/B7-1,"") | F8: 77.71 | H8: 82.19 | I8: =IF(ISNUMBER(H8),H8/H$65*100,"") | J8: =IF(AND(ISNUMBER(H8),ISNUMBER(H7)),H8/H7-1,"") | L8: 81.8 | N8: 79.32 | O8: =IF(ISNUMBER(N8),N8/N$65*100,"") | P8: =IF(AND(ISNUMBER(N8),ISNUMBER(N7)),N8/N7-1,"") | R8: 78.99 | T8: 77.93 | U8: =IF(ISNUMBER(T8),T8/T$65*100,"") | V8: =IF(AND(ISNUMBER(T8),ISNUMBER(T7)),T8/T7-1,"") | X8: 77.32 | Z8: 78.89 | AA8: =IF(ISNUMBER(Z8),Z8/Z$65*100,"") | AB8: =IF(AND(ISNUMBER(Z8),ISNUMBER(Z7)),Z8/Z7-1,"") | AD8: 78.97 | AF8: 70.49 | AG8: =IF(ISNUMBER(AF8),AF8/AF$65*100,"") | AH8: =IF(AND(ISNUMBER(AF8),ISNUMBER(AF7)),AF8/AF7-1,"") | AJ8: 70.32 | AL8: 69.86 | AM8: =IF(ISNUMBER(AL8),AL8/AL$65*100,"") | AN8: =IF(AND(ISNUMBER(AL8),ISNUMBER(AL7)),AL8/AL7-1,"") | AP8: 69.86 | AR8: 78.64 | AS8: =IF(ISNUMBER(AR8),AR8/AR$65*100,"") | AT8: =IF(AND(ISNUMBER(AR8),ISNUMBER(AR7)),AR8/AR7-1,"") | AV8: 78.4516
A9: 42125 | B9: 78.22 | C9: =IF(ISNUMBER(B9),B9/B$65*100,"") | D9: =IF(AND(ISNUMBER(B9),ISNUMBER(B8)),B9/B8-1,"") | F9: 77.84 | H9: 82.37 | I9: =IF(ISNUMBER(H9),H9/H$65*100,"") | J9: =IF(AND(ISNUMBER(H9),ISNUMBER(H8)),H9/H8-1,"") | L9: 81.88 | N9: 79.48 | O9: =IF(ISNUMBER(N9),N9/N$65*100,"") | P9: =IF(AND(ISNUMBER(N9),ISNUMBER(N8)),N9/N8-1,"") | R9: 79.05 | T9: 78.11 | U9: =IF(ISNUMBER(T9),T9/T$65*100,"") | V9: =IF(AND(ISNUMBER(T9),ISNUMBER(T8)),T9/T8-1,"") | X9: 77.47 | Z9: 79.16 | AA9: =IF(ISNUMBER(Z9),Z9/Z$65*100,"") | AB9: =IF(AND(ISNUMBER(Z9),ISNUMBER(Z8)),Z9/Z8-1,"") | AD9: 79.08 | AF9: 70.59 | AG9: =IF(ISNUMBER(AF9),AF9/AF$65*100,"") | AH9: =IF(AND(ISNUMBER(AF9),ISNUMBER(AF8)),AF9/AF8-1,"") | AJ9: 70.34 | AL9: 70.52 | AM9: =IF(ISNUMBER(AL9),AL9/AL$65*100,"") | AN9: =IF(AND(ISNUMBER(AL9),ISNUMBER(AL8)),AL9/AL8-1,"") | AP9: 70.52 | AR9: 79.22 | AS9: =IF(ISNUMBER(AR9),AR9/AR$65*100,"") | AT9: =IF(AND(ISNUMBER(AR9),ISNUMBER(AR8)),AR9/AR8-1,"") | AV9: 79.103
A10: 42156 | B10: 78.23 | C10: =IF(ISNUMBER(B10),B10/B$65*100,"") | D10: =IF(AND(ISNUMBER(B10),ISNUMBER(B9)),B10/B9-1,"") | F10: 77.88 | G10: =IF(COUNT(F5:F10)=6,(AVERAGE(F8:F10)/AVERAGE(F5:F7))^4-1,"") | H10: 82.41 | I10: =IF(ISNUMBER(H10),H10/H$65*100,"") | J10: =IF(AND(ISNUMBER(H10),ISNUMBER(H9)),H10/H9-1,"") | L10: 81.92 | M10: =IF(COUNT(L5:L10)=6,(AVERAGE(L8:L10)/AVERAGE(L5:L7))^4-1,"") | N10: 79.5 | O10: =IF(ISNUMBER(N10),N10/N$65*100,"") | P10: =IF(AND(ISNUMBER(N10),ISNUMBER(N9)),N10/N9-1,"") | R10: 79.1 | S10: =IF(COUNT(R5:R10)=6,(AVERAGE(R8:R10)/AVERAGE(R5:R7))^4-1,"") | T10: 77.96 | U10: =IF(ISNUMBER(T10),T10/T$65*100,"") | V10: =IF(AND(ISNUMBER(T10),ISNUMBER(T9)),T10/T9-1,"") | X10: 77.5 | Y10: =IF(COUNT(X5:X10)=6,(AVERAGE(X8:X10)/AVERAGE(X5:X7))^4-1,"") | Z10: 79.38 | AA10: =IF(ISNUMBER(Z10),Z10/Z$65*100,"") | AB10: =IF(AND(ISNUMBER(Z10),ISNUMBER(Z9)),Z10/Z9-1,"") | AD10: 79.11 | AE10: =IF(COUNT(AD5:AD10)=6,(AVERAGE(AD8:AD10)/AVERAGE(AD5:AD7))^4-1,"") | AF10: 70.55 | AG10: =IF(ISNUMBER(AF10),AF10/AF$65*100,"") | AH10: =IF(AND(ISNUMBER(AF10),ISNUMBER(AF9)),AF10/AF9-1,"") | AJ10: 70.39 | AK10: =IF(COUNT(AJ5:AJ10)=6,(AVERAGE(AJ8:AJ10)/AVERAGE(AJ5:AJ7))^4-1,"") | AL10: 70.44 | AM10: =IF(ISNUMBER(AL10),AL10/AL$65*100,"") | AN10: =IF(AND(ISNUMBER(AL10),ISNUMBER(AL9)),AL10/AL9-1,"") | AP10: 70.44 | AQ10: =IF(COUNT(AP5:AP10)=6,(AVERAGE(AP8:AP10)/AVERAGE(AP5:AP7))^4-1,"") | AR10: 79.34 | AS10: =IF(ISNUMBER(AR10),AR10/AR$65*100,"") | AT10: =IF(AND(ISNUMBER(AR10),ISNUMBER(AR9)),AR10/AR9-1,"") | AV10: 79.1045 | AW10: =IF(COUNT(AV5:AV10)=6,(AVERAGE(AV8:AV10)/AVERAGE(AV5:AV7))^4-1,"")
A11: 42186 | B11: 77.76 | C11: =IF(ISNUMBER(B11),B11/B$65*100,"") | D11: =IF(AND(ISNUMBER(B11),ISNUMBER(B10)),B11/B10-1,"") | F11: 77.79 | G11: =IF(COUNT(F6:F11)=6,(AVERAGE(F9:F11)/AVERAGE(F6:F8))^4-1,"") | H11: 81.89 | I11: =IF(ISNUMBER(H11),H11/H$65*100,"") | J11: =IF(AND(ISNUMBER(H11),ISNUMBER(H10)),H11/H10-1,"") | L11: 81.93 | M11: =IF(COUNT(L6:L11)=6,(AVERAGE(L9:L11)/AVERAGE(L6:L8))^4-1,"") | N11: 79.03 | O11: =IF(ISNUMBER(N11),N11/N$65*100,"") | P11: =IF(AND(ISNUMBER(N11),ISNUMBER(N10)),N11/N10-1,"") | R11: 79.07 | S11: =IF(COUNT(R6:R11)=6,(AVERAGE(R9:R11)/AVERAGE(R6:R8))^4-1,"") | T11: 76.45 | U11: =IF(ISNUMBER(T11),T11/T$65*100,"") | V11: =IF(AND(ISNUMBER(T11),ISNUMBER(T10)),T11/T10-1,"") | X11: 77.37 | Y11: =IF(COUNT(X6:X11)=6,(AVERAGE(X9:X11)/AVERAGE(X6:X8))^4-1,"") | Z11: 80.27 | AA11: =IF(ISNUMBER(Z11),Z11/Z$65*100,"") | AB11: =IF(AND(ISNUMBER(Z11),ISNUMBER(Z10)),Z11/Z10-1,"") | AD11: 79.09 | AE11: =IF(COUNT(AD6:AD11)=6,(AVERAGE(AD9:AD11)/AVERAGE(AD6:AD8))^4-1,"") | AF11: 70.22 | AG11: =IF(ISNUMBER(AF11),AF11/AF$65*100,"") | AH11: =IF(AND(ISNUMBER(AF11),ISNUMBER(AF10)),AF11/AF10-1,"") | AJ11: 70.26 | AK11: =IF(COUNT(AJ6:AJ11)=6,(AVERAGE(AJ9:AJ11)/AVERAGE(AJ6:AJ8))^4-1,"") | AL11: 69.95 | AM11: =IF(ISNUMBER(AL11),AL11/AL$65*100,"") | AN11: =IF(AND(ISNUMBER(AL11),ISNUMBER(AL10)),AL11/AL10-1,"") | AP11: 69.95 | AQ11: =IF(COUNT(AP6:AP11)=6,(AVERAGE(AP9:AP11)/AVERAGE(AP6:AP8))^4-1,"") | AR11: 79.79 | AS11: =IF(ISNUMBER(AR11),AR11/AR$65*100,"") | AT11: =IF(AND(ISNUMBER(AR11),ISNUMBER(AR10)),AR11/AR10-1,"") | AV11: 79.153 | AW11: =IF(COUNT(AV6:AV11)=6,(AVERAGE(AV9:AV11)/AVERAGE(AV6:AV8))^4-1,"")
A12: 42217 | B12: 77.76 | C12: =IF(ISNUMBER(B12),B12/B$65*100,"") | D12: =IF(AND(ISNUMBER(B12),ISNUMBER(B11)),B12/B11-1,"") | F12: 77.75 | G12: =IF(COUNT(F7:F12)=6,(AVERAGE(F10:F12)/AVERAGE(F7:F9))^4-1,"") | H12: 82.14 | I12: =IF(ISNUMBER(H12),H12/H$65*100,"") | J12: =IF(AND(ISNUMBER(H12),ISNUMBER(H11)),H12/H11-1,"") | L12: 82.03 | M12: =IF(COUNT(L7:L12)=6,(AVERAGE(L10:L12)/AVERAGE(L7:L9))^4-1,"") | N12: 79.24 | O12: =IF(ISNUMBER(N12),N12/N$65*100,"") | P12: =IF(AND(ISNUMBER(N12),ISNUMBER(N11)),N12/N11-1,"") | R12: 79.22 | S12: =IF(COUNT(R7:R12)=6,(AVERAGE(R10:R12)/AVERAGE(R7:R9))^4-1,"") | T12: 76.28 | U12: =IF(ISNUMBER(T12),T12/T$65*100,"") | V12: =IF(AND(ISNUMBER(T12),ISNUMBER(T11)),T12/T11-1,"") | X12: 77.21 | Y12: =IF(COUNT(X7:X12)=6,(AVERAGE(X10:X12)/AVERAGE(X7:X9))^4-1,"") | Z12: 80.5 | AA12: =IF(ISNUMBER(Z12),Z12/Z$65*100,"") | AB12: =IF(AND(ISNUMBER(Z12),ISNUMBER(Z11)),Z12/Z11-1,"") | AD12: 79.2 | AE12: =IF(COUNT(AD7:AD12)=6,(AVERAGE(AD10:AD12)/AVERAGE(AD7:AD9))^4-1,"") | AF12: 70.3 | AG12: =IF(ISNUMBER(AF12),AF12/AF$65*100,"") | AH12: =IF(AND(ISNUMBER(AF12),ISNUMBER(AF11)),AF12/AF11-1,"") | AJ12: 70.57 | AK12: =IF(COUNT(AJ7:AJ12)=6,(AVERAGE(AJ10:AJ12)/AVERAGE(AJ7:AJ9))^4-1,"") | AL12: 68.41 | AM12: =IF(ISNUMBER(AL12),AL12/AL$65*100,"") | AN12: =IF(AND(ISNUMBER(AL12),ISNUMBER(AL11)),AL12/AL11-1,"") | AP12: 68.41 | AQ12: =IF(COUNT(AP7:AP12)=6,(AVERAGE(AP10:AP12)/AVERAGE(AP7:AP9))^4-1,"") | AR12: 79.01 | AS12: =IF(ISNUMBER(AR12),AR12/AR$65*100,"") | AT12: =IF(AND(ISNUMBER(AR12),ISNUMBER(AR11)),AR12/AR11-1,"") | AV12: 78.2293 | AW12: =IF(COUNT(AV7:AV12)=6,(AVERAGE(AV10:AV12)/AVERAGE(AV7:AV9))^4-1,"")
A13: 42248 | B13: 77.92 | C13: =IF(ISNUMBER(B13),B13/B$65*100,"") | D13: =IF(AND(ISNUMBER(B13),ISNUMBER(B12)),B13/B12-1,"") | F13: 77.69 | G13: =IF(COUNT(F8:F13)=6,(AVERAGE(F11:F13)/AVERAGE(F8:F10))^4-1,"") | H13: 82.53 | I13: =IF(ISNUMBER(H13),H13/H$65*100,"") | J13: =IF(AND(ISNUMBER(H13),ISNUMBER(H12)),H13/H12-1,"") | L13: 82.09 | M13: =IF(COUNT(L8:L13)=6,(AVERAGE(L11:L13)/AVERAGE(L8:L10))^4-1,"") | N13: 79.58 | O13: =IF(ISNUMBER(N13),N13/N$65*100,"") | P13: =IF(AND(ISNUMBER(N13),ISNUMBER(N12)),N13/N12-1,"") | R13: 79.32 | S13: =IF(COUNT(R8:R13)=6,(AVERAGE(R11:R13)/AVERAGE(R8:R10))^4-1,"") | T13: 77.22 | U13: =IF(ISNUMBER(T13),T13/T$65*100,"") | V13: =IF(AND(ISNUMBER(T13),ISNUMBER(T12)),T13/T12-1,"") | X13: 77.04 | Y13: =IF(COUNT(X8:X13)=6,(AVERAGE(X11:X13)/AVERAGE(X8:X10))^4-1,"") | Z13: 79.63 | AA13: =IF(ISNUMBER(Z13),Z13/Z$65*100,"") | AB13: =IF(AND(ISNUMBER(Z13),ISNUMBER(Z12)),Z13/Z12-1,"") | AD13: 79.3 | AE13: =IF(COUNT(AD8:AD13)=6,(AVERAGE(AD11:AD13)/AVERAGE(AD8:AD10))^4-1,"") | AF13: 70.49 | AG13: =IF(ISNUMBER(AF13),AF13/AF$65*100,"") | AH13: =IF(AND(ISNUMBER(AF13),ISNUMBER(AF12)),AF13/AF12-1,"") | AJ13: 70.77 | AK13: =IF(COUNT(AJ8:AJ13)=6,(AVERAGE(AJ11:AJ13)/AVERAGE(AJ8:AJ10))^4-1,"") | AL13: 67.25 | AM13: =IF(ISNUMBER(AL13),AL13/AL$65*100,"") | AN13: =IF(AND(ISNUMBER(AL13),ISNUMBER(AL12)),AL13/AL12-1,"") | AP13: 67.25 | AQ13: =IF(COUNT(AP8:AP13)=6,(AVERAGE(AP11:AP13)/AVERAGE(AP8:AP10))^4-1,"") | AR13: 77.37 | AS13: =IF(ISNUMBER(AR13),AR13/AR$65*100,"") | AT13: =IF(AND(ISNUMBER(AR13),ISNUMBER(AR12)),AR13/AR12-1,"") | AV13: 77.3626 | AW13: =IF(COUNT(AV8:AV13)=6,(AVERAGE(AV11:AV13)/AVERAGE(AV8:AV10))^4-1,"")
A14: 42278 | B14: 78.02 | C14: =IF(ISNUMBER(B14),B14/B$65*100,"") | D14: =IF(AND(ISNUMBER(B14),ISNUMBER(B13)),B14/B13-1,"") | F14: 77.75 | G14: =IF(COUNT(F9:F14)=6,(AVERAGE(F12:F14)/AVERAGE(F9:F11))^4-1,"") | H14: 82.65 | I14: =IF(ISNUMBER(H14),H14/H$65*100,"") | J14: =IF(AND(ISNUMBER(H14),ISNUMBER(H13)),H14/H13-1,"") | L14: 82.21 | M14: =IF(COUNT(L9:L14)=6,(AVERAGE(L12:L14)/AVERAGE(L9:L11))^4-1,"") | N14: 79.73 | O14: =IF(ISNUMBER(N14),N14/N$65*100,"") | P14: =IF(AND(ISNUMBER(N14),ISNUMBER(N13)),N14/N13-1,"") | R14: 79.43 | S14: =IF(COUNT(R9:R14)=6,(AVERAGE(R12:R14)/AVERAGE(R9:R11))^4-1,"") | T14: 77.48 | U14: =IF(ISNUMBER(T14),T14/T$65*100,"") | V14: =IF(AND(ISNUMBER(T14),ISNUMBER(T13)),T14/T13-1,"") | X14: 77.04 | Y14: =IF(COUNT(X9:X14)=6,(AVERAGE(X12:X14)/AVERAGE(X9:X11))^4-1,"") | Z14: 79.52 | AA14: =IF(ISNUMBER(Z14),Z14/Z$65*100,"") | AB14: =IF(AND(ISNUMBER(Z14),ISNUMBER(Z13)),Z14/Z13-1,"") | AD14: 79.43 | AE14: =IF(COUNT(AD9:AD14)=6,(AVERAGE(AD12:AD14)/AVERAGE(AD9:AD11))^4-1,"") | AF14: 70.74 | AG14: =IF(ISNUMBER(AF14),AF14/AF$65*100,"") | AH14: =IF(AND(ISNUMBER(AF14),ISNUMBER(AF13)),AF14/AF13-1,"") | AJ14: 70.86 | AK14: =IF(COUNT(AJ9:AJ14)=6,(AVERAGE(AJ12:AJ14)/AVERAGE(AJ9:AJ11))^4-1,"") | AL14: 66.89 | AM14: =IF(ISNUMBER(AL14),AL14/AL$65*100,"") | AN14: =IF(AND(ISNUMBER(AL14),ISNUMBER(AL13)),AL14/AL13-1,"") | AP14: 66.89 | AQ14: =IF(COUNT(AP9:AP14)=6,(AVERAGE(AP12:AP14)/AVERAGE(AP9:AP11))^4-1,"") | AR14: 77.13 | AS14: =IF(ISNUMBER(AR14),AR14/AR$65*100,"") | AT14: =IF(AND(ISNUMBER(AR14),ISNUMBER(AR13)),AR14/AR13-1,"") | AV14: 77.2885 | AW14: =IF(COUNT(AV9:AV14)=6,(AVERAGE(AV12:AV14)/AVERAGE(AV9:AV11))^4-1,"")
A15: 42309 | B15: 77.68 | C15: =IF(ISNUMBER(B15),B15/B$65*100,"") | D15: =IF(AND(ISNUMBER(B15),ISNUMBER(B14)),B15/B14-1,"") | F15: 77.79 | G15: =IF(COUNT(F10:F15)=6,(AVERAGE(F13:F15)/AVERAGE(F10:F12))^4-1,"") | H15: 82.15 | I15: =IF(ISNUMBER(H15),H15/H$65*100,"") | J15: =IF(AND(ISNUMBER(H15),ISNUMBER(H14)),H15/H14-1,"") | L15: 82.26 | M15: =IF(COUNT(L10:L15)=6,(AVERAGE(L13:L15)/AVERAGE(L10:L12))^4-1,"") | N15: 79.35 | O15: =IF(ISNUMBER(N15),N15/N$65*100,"") | P15: =IF(AND(ISNUMBER(N15),ISNUMBER(N14)),N15/N14-1,"") | R15: 79.48 | S15: =IF(COUNT(R10:R15)=6,(AVERAGE(R13:R15)/AVERAGE(R10:R12))^4-1,"") | T15: 77.48 | U15: =IF(ISNUMBER(T15),T15/T$65*100,"") | V15: =IF(AND(ISNUMBER(T15),ISNUMBER(T14)),T15/T14-1,"") | X15: 77.04 | Y15: =IF(COUNT(X10:X15)=6,(AVERAGE(X13:X15)/AVERAGE(X10:X12))^4-1,"") | Z15: 78.72 | AA15: =IF(ISNUMBER(Z15),Z15/Z$65*100,"") | AB15: =IF(AND(ISNUMBER(Z15),ISNUMBER(Z14)),Z15/Z14-1,"") | AD15: 79.53 | AE15: =IF(COUNT(AD10:AD15)=6,(AVERAGE(AD13:AD15)/AVERAGE(AD10:AD12))^4-1,"") | AF15: 70.74 | AG15: =IF(ISNUMBER(AF15),AF15/AF$65*100,"") | AH15: =IF(AND(ISNUMBER(AF15),ISNUMBER(AF14)),AF15/AF14-1,"") | AJ15: 70.9 | AK15: =IF(COUNT(AJ10:AJ15)=6,(AVERAGE(AJ13:AJ15)/AVERAGE(AJ10:AJ12))^4-1,"") | AL15: 66.89 | AM15: =IF(ISNUMBER(AL15),AL15/AL$65*100,"") | AN15: =IF(AND(ISNUMBER(AL15),ISNUMBER(AL14)),AL15/AL14-1,"") | AP15: 66.89 | AQ15: =IF(COUNT(AP10:AP15)=6,(AVERAGE(AP13:AP15)/AVERAGE(AP10:AP12))^4-1,"") | AR15: 76.81 | AS15: =IF(ISNUMBER(AR15),AR15/AR$65*100,"") | AT15: =IF(AND(ISNUMBER(AR15),ISNUMBER(AR14)),AR15/AR14-1,"") | AV15: 77.4191 | AW15: =IF(COUNT(AV10:AV15)=6,(AVERAGE(AV13:AV15)/AVERAGE(AV10:AV12))^4-1,"")
A16: 42339 | B16: 77.69 | C16: =IF(ISNUMBER(B16),B16/B$65*100,"") | D16: =IF(AND(ISNUMBER(B16),ISNUMBER(B15)),B16/B15-1,"") | F16: 77.63 | G16: =IF(COUNT(F11:F16)=6,(AVERAGE(F14:F16)/AVERAGE(F11:F13))^4-1,"") | H16: 82.44 | I16: =IF(ISNUMBER(H16),H16/H$65*100,"") | J16: =IF(AND(ISNUMBER(H16),ISNUMBER(H15)),H16/H15-1,"") | L16: 82.28 | M16: =IF(COUNT(L11:L16)=6,(AVERAGE(L14:L16)/AVERAGE(L11:L13))^4-1,"") | N16: 79.53 | O16: =IF(ISNUMBER(N16),N16/N$65*100,"") | P16: =IF(AND(ISNUMBER(N16),ISNUMBER(N15)),N16/N15-1,"") | R16: 79.45 | S16: =IF(COUNT(R11:R16)=6,(AVERAGE(R14:R16)/AVERAGE(R11:R13))^4-1,"") | T16: 77.06 | U16: =IF(ISNUMBER(T16),T16/T$65*100,"") | V16: =IF(AND(ISNUMBER(T16),ISNUMBER(T15)),T16/T15-1,"") | X16: 76.71 | Y16: =IF(COUNT(X11:X16)=6,(AVERAGE(X14:X16)/AVERAGE(X11:X13))^4-1,"") | Z16: 79.32 | AA16: =IF(ISNUMBER(Z16),Z16/Z$65*100,"") | AB16: =IF(AND(ISNUMBER(Z16),ISNUMBER(Z15)),Z16/Z15-1,"") | AD16: 79.58 | AE16: =IF(COUNT(AD11:AD16)=6,(AVERAGE(AD14:AD16)/AVERAGE(AD11:AD13))^4-1,"") | AF16: 70.57 | AG16: =IF(ISNUMBER(AF16),AF16/AF$65*100,"") | AH16: =IF(AND(ISNUMBER(AF16),ISNUMBER(AF15)),AF16/AF15-1,"") | AJ16: 70.72 | AK16: =IF(COUNT(AJ11:AJ16)=6,(AVERAGE(AJ14:AJ16)/AVERAGE(AJ11:AJ13))^4-1,"") | AL16: 65.68 | AM16: =IF(ISNUMBER(AL16),AL16/AL$65*100,"") | AN16: =IF(AND(ISNUMBER(AL16),ISNUMBER(AL15)),AL16/AL15-1,"") | AP16: 65.68 | AQ16: =IF(COUNT(AP11:AP16)=6,(AVERAGE(AP14:AP16)/AVERAGE(AP11:AP13))^4-1,"") | AR16: 76.55 | AS16: =IF(ISNUMBER(AR16),AR16/AR$65*100,"") | AT16: =IF(AND(ISNUMBER(AR16),ISNUMBER(AR15)),AR16/AR15-1,"") | AV16: 77.0792 | AW16: =IF(COUNT(AV11:AV16)=6,(AVERAGE(AV14:AV16)/AVERAGE(AV11:AV13))^4-1,"")
A17: 42370 | B17: 76.55 | C17: =IF(ISNUMBER(B17),B17/B$65*100,"") | D17: =IF(AND(ISNUMBER(B17),ISNUMBER(B16)),B17/B16-1,"") | E17: =IF(AND(ISNUMBER(B17),ISNUMBER(B5)),B17/B5-1,"") | F17: 77.44 | G17: =IF(COUNT(F12:F17)=6,(AVERAGE(F15:F17)/AVERAGE(F12:F14))^4-1,"") | H17: 80.99 | I17: =IF(ISNUMBER(H17),H17/H$65*100,"") | J17: =IF(AND(ISNUMBER(H17),ISNUMBER(H16)),H17/H16-1,"") | K17: =IF(AND(ISNUMBER(H17),ISNUMBER(H5)),H17/H5-1,"") | L17: 82.36 | M17: =IF(COUNT(L12:L17)=6,(AVERAGE(L15:L17)/AVERAGE(L12:L14))^4-1,"") | N17: 78.47 | O17: =IF(ISNUMBER(N17),N17/N$65*100,"") | P17: =IF(AND(ISNUMBER(N17),ISNUMBER(N16)),N17/N16-1,"") | Q17: =IF(AND(ISNUMBER(N17),ISNUMBER(N5)),N17/N5-1,"") | R17: 79.47 | S17: =IF(COUNT(R12:R17)=6,(AVERAGE(R15:R17)/AVERAGE(R12:R14))^4-1,"") | T17: 75.4 | U17: =IF(ISNUMBER(T17),T17/T$65*100,"") | V17: =IF(AND(ISNUMBER(T17),ISNUMBER(T16)),T17/T16-1,"") | W17: =IF(AND(ISNUMBER(T17),ISNUMBER(T5)),T17/T5-1,"") | X17: 76.29 | Y17: =IF(COUNT(X12:X17)=6,(AVERAGE(X15:X17)/AVERAGE(X12:X14))^4-1,"") | Z17: 78.83 | AA17: =IF(ISNUMBER(Z17),Z17/Z$65*100,"") | AB17: =IF(AND(ISNUMBER(Z17),ISNUMBER(Z16)),Z17/Z16-1,"") | AC17: =IF(AND(ISNUMBER(Z17),ISNUMBER(Z5)),Z17/Z5-1,"") | AD17: 79.68 | AE17: =IF(COUNT(AD12:AD17)=6,(AVERAGE(AD15:AD17)/AVERAGE(AD12:AD14))^4-1,"") | AF17: 70.69 | AG17: =IF(ISNUMBER(AF17),AF17/AF$65*100,"") | AH17: =IF(AND(ISNUMBER(AF17),ISNUMBER(AF16)),AF17/AF16-1,"") | AI17: =IF(AND(ISNUMBER(AF17),ISNUMBER(AF5)),AF17/AF5-1,"") | AJ17: 70.55 | AK17: =IF(COUNT(AJ12:AJ17)=6,(AVERAGE(AJ15:AJ17)/AVERAGE(AJ12:AJ14))^4-1,"") | AL17: 63.89 | AM17: =IF(ISNUMBER(AL17),AL17/AL$65*100,"") | AN17: =IF(AND(ISNUMBER(AL17),ISNUMBER(AL16)),AL17/AL16-1,"") | AO17: =IF(AND(ISNUMBER(AL17),ISNUMBER(AL5)),AL17/AL5-1,"") | AP17: 63.89 | AQ17: =IF(COUNT(AP12:AP17)=6,(AVERAGE(AP15:AP17)/AVERAGE(AP12:AP14))^4-1,"") | AR17: 75.56 | AS17: =IF(ISNUMBER(AR17),AR17/AR$65*100,"") | AT17: =IF(AND(ISNUMBER(AR17),ISNUMBER(AR16)),AR17/AR16-1,"") | AU17: =IF(AND(ISNUMBER(AR17),ISNUMBER(AR5)),AR17/AR5-1,"") | AV17: 75.7993 | AW17: =IF(COUNT(AV12:AV17)=6,(AVERAGE(AV15:AV17)/AVERAGE(AV12:AV14))^4-1,"")
A18: 42401 | B18: 76.68 | C18: =IF(ISNUMBER(B18),B18/B$65*100,"") | D18: =IF(AND(ISNUMBER(B18),ISNUMBER(B17)),B18/B17-1,"") | E18: =IF(AND(ISNUMBER(B18),ISNUMBER(B6)),B18/B6-1,"") | F18: 77.39 | G18: =IF(COUNT(F13:F18)=6,(AVERAGE(F16:F18)/AVERAGE(F13:F15))^4-1,"") | H18: 81.32 | I18: =IF(ISNUMBER(H18),H18/H$65*100,"") | J18: =IF(AND(ISNUMBER(H18),ISNUMBER(H17)),H18/H17-1,"") | K18: =IF(AND(ISNUMBER(H18),ISNUMBER(H6)),H18/H6-1,"") | L18: 82.44 | M18: =IF(COUNT(L13:L18)=6,(AVERAGE(L16:L18)/AVERAGE(L13:L15))^4-1,"") | N18: 78.72 | O18: =IF(ISNUMBER(N18),N18/N$65*100,"") | P18: =IF(AND(ISNUMBER(N18),ISNUMBER(N17)),N18/N17-1,"") | Q18: =IF(AND(ISNUMBER(N18),ISNUMBER(N6)),N18/N6-1,"") | R18: 79.53 | S18: =IF(COUNT(R13:R18)=6,(AVERAGE(R16:R18)/AVERAGE(R13:R15))^4-1,"") | T18: 75.36 | U18: =IF(ISNUMBER(T18),T18/T$65*100,"") | V18: =IF(AND(ISNUMBER(T18),ISNUMBER(T17)),T18/T17-1,"") | W18: =IF(AND(ISNUMBER(T18),ISNUMBER(T6)),T18/T6-1,"") | X18: 76.19 | Y18: =IF(COUNT(X13:X18)=6,(AVERAGE(X16:X18)/AVERAGE(X13:X15))^4-1,"") | Z18: 79.18 | AA18: =IF(ISNUMBER(Z18),Z18/Z$65*100,"") | AB18: =IF(AND(ISNUMBER(Z18),ISNUMBER(Z17)),Z18/Z17-1,"") | AC18: =IF(AND(ISNUMBER(Z18),ISNUMBER(Z6)),Z18/Z6-1,"") | AD18: 79.72 | AE18: =IF(COUNT(AD13:AD18)=6,(AVERAGE(AD16:AD18)/AVERAGE(AD13:AD15))^4-1,"") | AF18: 70.71 | AG18: =IF(ISNUMBER(AF18),AF18/AF$65*100,"") | AH18: =IF(AND(ISNUMBER(AF18),ISNUMBER(AF17)),AF18/AF17-1,"") | AI18: =IF(AND(ISNUMBER(AF18),ISNUMBER(AF6)),AF18/AF6-1,"") | AJ18: 70.55 | AK18: =IF(COUNT(AJ13:AJ18)=6,(AVERAGE(AJ16:AJ18)/AVERAGE(AJ13:AJ15))^4-1,"") | AL18: 63.05 | AM18: =IF(ISNUMBER(AL18),AL18/AL$65*100,"") | AN18: =IF(AND(ISNUMBER(AL18),ISNUMBER(AL17)),AL18/AL17-1,"") | AO18: =IF(AND(ISNUMBER(AL18),ISNUMBER(AL6)),AL18/AL6-1,"") | AP18: 63.05 | AQ18: =IF(COUNT(AP13:AP18)=6,(AVERAGE(AP16:AP18)/AVERAGE(AP13:AP15))^4-1,"") | AR18: 75.22 | AS18: =IF(ISNUMBER(AR18),AR18/AR$65*100,"") | AT18: =IF(AND(ISNUMBER(AR18),ISNUMBER(AR17)),AR18/AR17-1,"") | AU18: =IF(AND(ISNUMBER(AR18),ISNUMBER(AR6)),AR18/AR6-1,"") | AV18: 75.2531 | AW18: =IF(COUNT(AV13:AV18)=6,(AVERAGE(AV16:AV18)/AVERAGE(AV13:AV15))^4-1,"")
A19: 42430 | B19: 77.64 | C19: =IF(ISNUMBER(B19),B19/B$65*100,"") | D19: =IF(AND(ISNUMBER(B19),ISNUMBER(B18)),B19/B18-1,"") | E19: =IF(AND(ISNUMBER(B19),ISNUMBER(B7)),B19/B7-1,"") | F19: 77.53 | G19: =IF(COUNT(F14:F19)=6,(AVERAGE(F17:F19)/AVERAGE(F14:F16))^4-1,"") | H19: 82.6 | I19: =IF(ISNUMBER(H19),H19/H$65*100,"") | J19: =IF(AND(ISNUMBER(H19),ISNUMBER(H18)),H19/H18-1,"") | K19: =IF(AND(ISNUMBER(H19),ISNUMBER(H7)),H19/H7-1,"") | L19: 82.49 | M19: =IF(COUNT(L14:L19)=6,(AVERAGE(L17:L19)/AVERAGE(L14:L16))^4-1,"") | N19: 79.72 | O19: =IF(ISNUMBER(N19),N19/N$65*100,"") | P19: =IF(AND(ISNUMBER(N19),ISNUMBER(N18)),N19/N18-1,"") | Q19: =IF(AND(ISNUMBER(N19),ISNUMBER(N7)),N19/N7-1,"") | R19: 79.6 | S19: =IF(COUNT(R14:R19)=6,(AVERAGE(R17:R19)/AVERAGE(R14:R16))^4-1,"") | T19: 76.77 | U19: =IF(ISNUMBER(T19),T19/T$65*100,"") | V19: =IF(AND(ISNUMBER(T19),ISNUMBER(T18)),T19/T18-1,"") | W19: =IF(AND(ISNUMBER(T19),ISNUMBER(T7)),T19/T7-1,"") | X19: 76.38 | Y19: =IF(COUNT(X14:X19)=6,(AVERAGE(X17:X19)/AVERAGE(X14:X16))^4-1,"") | Z19: 79.57 | AA19: =IF(ISNUMBER(Z19),Z19/Z$65*100,"") | AB19: =IF(AND(ISNUMBER(Z19),ISNUMBER(Z18)),Z19/Z18-1,"") | AC19: =IF(AND(ISNUMBER(Z19),ISNUMBER(Z7)),Z19/Z7-1,"") | AD19: 79.79 | AE19: =IF(COUNT(AD14:AD19)=6,(AVERAGE(AD17:AD19)/AVERAGE(AD14:AD16))^4-1,"") | AF19: 70.86 | AG19: =IF(ISNUMBER(AF19),AF19/AF$65*100,"") | AH19: =IF(AND(ISNUMBER(AF19),ISNUMBER(AF18)),AF19/AF18-1,"") | AI19: =IF(AND(ISNUMBER(AF19),ISNUMBER(AF7)),AF19/AF7-1,"") | AJ19: 70.69 | AK19: =IF(COUNT(AJ14:AJ19)=6,(AVERAGE(AJ17:AJ19)/AVERAGE(AJ14:AJ16))^4-1,"") | AL19: 63.71 | AM19: =IF(ISNUMBER(AL19),AL19/AL$65*100,"") | AN19: =IF(AND(ISNUMBER(AL19),ISNUMBER(AL18)),AL19/AL18-1,"") | AO19: =IF(AND(ISNUMBER(AL19),ISNUMBER(AL7)),AL19/AL7-1,"") | AP19: 63.71 | AQ19: =IF(COUNT(AP14:AP19)=6,(AVERAGE(AP17:AP19)/AVERAGE(AP14:AP16))^4-1,"") | AR19: 75.79 | AS19: =IF(ISNUMBER(AR19),AR19/AR$65*100,"") | AT19: =IF(AND(ISNUMBER(AR19),ISNUMBER(AR18)),AR19/AR18-1,"") | AU19: =IF(AND(ISNUMBER(AR19),ISNUMBER(AR7)),AR19/AR7-1,"") | AV19: 76.2251 | AW19: =IF(COUNT(AV14:AV19)=6,(AVERAGE(AV17:AV19)/AVERAGE(AV14:AV16))^4-1,"")
A20: 42461 | B20: 77.8 | C20: =IF(ISNUMBER(B20),B20/B$65*100,"") | D20: =IF(AND(ISNUMBER(B20),ISNUMBER(B19)),B20/B19-1,"") | E20: =IF(AND(ISNUMBER(B20),ISNUMBER(B8)),B20/B8-1,"") | F20: 77.59 | G20: =IF(COUNT(F15:F20)=6,(AVERAGE(F18:F20)/AVERAGE(F15:F17))^4-1,"") | H20: 82.78 | I20: =IF(ISNUMBER(H20),H20/H$65*100,"") | J20: =IF(AND(ISNUMBER(H20),ISNUMBER(H19)),H20/H19-1,"") | K20: =IF(AND(ISNUMBER(H20),ISNUMBER(H8)),H20/H8-1,"") | L20: 82.51 | M20: =IF(COUNT(L15:L20)=6,(AVERAGE(L18:L20)/AVERAGE(L15:L17))^4-1,"") | N20: 79.91 | O20: =IF(ISNUMBER(N20),N20/N$65*100,"") | P20: =IF(AND(ISNUMBER(N20),ISNUMBER(N19)),N20/N19-1,"") | Q20: =IF(AND(ISNUMBER(N20),ISNUMBER(N8)),N20/N8-1,"") | R20: 79.66 | S20: =IF(COUNT(R15:R20)=6,(AVERAGE(R18:R20)/AVERAGE(R15:R17))^4-1,"") | T20: 77.07 | U20: =IF(ISNUMBER(T20),T20/T$65*100,"") | V20: =IF(AND(ISNUMBER(T20),ISNUMBER(T19)),T20/T19-1,"") | W20: =IF(AND(ISNUMBER(T20),ISNUMBER(T8)),T20/T8-1,"") | X20: 76.47 | Y20: =IF(COUNT(X15:X20)=6,(AVERAGE(X18:X20)/AVERAGE(X15:X17))^4-1,"") | Z20: 79.55 | AA20: =IF(ISNUMBER(Z20),Z20/Z$65*100,"") | AB20: =IF(AND(ISNUMBER(Z20),ISNUMBER(Z19)),Z20/Z19-1,"") | AC20: =IF(AND(ISNUMBER(Z20),ISNUMBER(Z8)),Z20/Z8-1,"") | AD20: 79.81 | AE20: =IF(COUNT(AD15:AD20)=6,(AVERAGE(AD18:AD20)/AVERAGE(AD15:AD17))^4-1,"") | AF20: 71.05 | AG20: =IF(ISNUMBER(AF20),AF20/AF$65*100,"") | AH20: =IF(AND(ISNUMBER(AF20),ISNUMBER(AF19)),AF20/AF19-1,"") | AI20: =IF(AND(ISNUMBER(AF20),ISNUMBER(AF8)),AF20/AF8-1,"") | AJ20: 70.87 | AK20: =IF(COUNT(AJ15:AJ20)=6,(AVERAGE(AJ18:AJ20)/AVERAGE(AJ15:AJ17))^4-1,"") | AL20: 63.76 | AM20: =IF(ISNUMBER(AL20),AL20/AL$65*100,"") | AN20: =IF(AND(ISNUMBER(AL20),ISNUMBER(AL19)),AL20/AL19-1,"") | AO20: =IF(AND(ISNUMBER(AL20),ISNUMBER(AL8)),AL20/AL8-1,"") | AP20: 63.76 | AQ20: =IF(COUNT(AP15:AP20)=6,(AVERAGE(AP18:AP20)/AVERAGE(AP15:AP17))^4-1,"") | AR20: 76.31 | AS20: =IF(ISNUMBER(AR20),AR20/AR$65*100,"") | AT20: =IF(AND(ISNUMBER(AR20),ISNUMBER(AR19)),AR20/AR19-1,"") | AU20: =IF(AND(ISNUMBER(AR20),ISNUMBER(AR8)),AR20/AR8-1,"") | AV20: 76.2086 | AW20: =IF(COUNT(AV15:AV20)=6,(AVERAGE(AV18:AV20)/AVERAGE(AV15:AV17))^4-1,"")
A21: 42491 | B21: 78.13 | C21: =IF(ISNUMBER(B21),B21/B$65*100,"") | D21: =IF(AND(ISNUMBER(B21),ISNUMBER(B20)),B21/B20-1,"") | E21: =IF(AND(ISNUMBER(B21),ISNUMBER(B9)),B21/B9-1,"") | F21: 77.74 | G21: =IF(COUNT(F16:F21)=6,(AVERAGE(F19:F21)/AVERAGE(F16:F18))^4-1,"") | H21: 83.03 | I21: =IF(ISNUMBER(H21),H21/H$65*100,"") | J21: =IF(AND(ISNUMBER(H21),ISNUMBER(H20)),H21/H20-1,"") | K21: =IF(AND(ISNUMBER(H21),ISNUMBER(H9)),H21/H9-1,"") | L21: 82.54 | M21: =IF(COUNT(L16:L21)=6,(AVERAGE(L19:L21)/AVERAGE(L16:L18))^4-1,"") | N21: 80.14 | O21: =IF(ISNUMBER(N21),N21/N$65*100,"") | P21: =IF(AND(ISNUMBER(N21),ISNUMBER(N20)),N21/N20-1,"") | Q21: =IF(AND(ISNUMBER(N21),ISNUMBER(N9)),N21/N9-1,"") | R21: 79.7 | S21: =IF(COUNT(R16:R21)=6,(AVERAGE(R19:R21)/AVERAGE(R16:R18))^4-1,"") | T21: 77.37 | U21: =IF(ISNUMBER(T21),T21/T$65*100,"") | V21: =IF(AND(ISNUMBER(T21),ISNUMBER(T20)),T21/T20-1,"") | W21: =IF(AND(ISNUMBER(T21),ISNUMBER(T9)),T21/T9-1,"") | X21: 76.72 | Y21: =IF(COUNT(X16:X21)=6,(AVERAGE(X19:X21)/AVERAGE(X16:X18))^4-1,"") | Z21: 79.92 | AA21: =IF(ISNUMBER(Z21),Z21/Z$65*100,"") | AB21: =IF(AND(ISNUMBER(Z21),ISNUMBER(Z20)),Z21/Z20-1,"") | AC21: =IF(AND(ISNUMBER(Z21),ISNUMBER(Z9)),Z21/Z9-1,"") | AD21: 79.83 | AE21: =IF(COUNT(AD16:AD21)=6,(AVERAGE(AD19:AD21)/AVERAGE(AD16:AD18))^4-1,"") | AF21: 71.23 | AG21: =IF(ISNUMBER(AF21),AF21/AF$65*100,"") | AH21: =IF(AND(ISNUMBER(AF21),ISNUMBER(AF20)),AF21/AF20-1,"") | AI21: =IF(AND(ISNUMBER(AF21),ISNUMBER(AF9)),AF21/AF9-1,"") | AJ21: 70.94 | AK21: =IF(COUNT(AJ16:AJ21)=6,(AVERAGE(AJ19:AJ21)/AVERAGE(AJ16:AJ18))^4-1,"") | AL21: 64.81 | AM21: =IF(ISNUMBER(AL21),AL21/AL$65*100,"") | AN21: =IF(AND(ISNUMBER(AL21),ISNUMBER(AL20)),AL21/AL20-1,"") | AO21: =IF(AND(ISNUMBER(AL21),ISNUMBER(AL9)),AL21/AL9-1,"") | AP21: 64.81 | AQ21: =IF(COUNT(AP16:AP21)=6,(AVERAGE(AP19:AP21)/AVERAGE(AP16:AP18))^4-1,"") | AR21: 76.97 | AS21: =IF(ISNUMBER(AR21),AR21/AR$65*100,"") | AT21: =IF(AND(ISNUMBER(AR21),ISNUMBER(AR20)),AR21/AR20-1,"") | AU21: =IF(AND(ISNUMBER(AR21),ISNUMBER(AR9)),AR21/AR9-1,"") | AV21: 76.8446 | AW21: =IF(COUNT(AV16:AV21)=6,(AVERAGE(AV19:AV21)/AVERAGE(AV16:AV18))^4-1,"")
A22: 42522 | B22: 78.27 | C22: =IF(ISNUMBER(B22),B22/B$65*100,"") | D22: =IF(AND(ISNUMBER(B22),ISNUMBER(B21)),B22/B21-1,"") | E22: =IF(AND(ISNUMBER(B22),ISNUMBER(B10)),B22/B10-1,"") | F22: 77.9 | G22: =IF(COUNT(F17:F22)=6,(AVERAGE(F20:F22)/AVERAGE(F17:F19))^4-1,"") | H22: 83.07 | I22: =IF(ISNUMBER(H22),H22/H$65*100,"") | J22: =IF(AND(ISNUMBER(H22),ISNUMBER(H21)),H22/H21-1,"") | K22: =IF(AND(ISNUMBER(H22),ISNUMBER(H10)),H22/H10-1,"") | L22: 82.56 | M22: =IF(COUNT(L17:L22)=6,(AVERAGE(L20:L22)/AVERAGE(L17:L19))^4-1,"") | N22: 80.15 | O22: =IF(ISNUMBER(N22),N22/N$65*100,"") | P22: =IF(AND(ISNUMBER(N22),ISNUMBER(N21)),N22/N21-1,"") | Q22: =IF(AND(ISNUMBER(N22),ISNUMBER(N10)),N22/N10-1,"") | R22: 79.73 | S22: =IF(COUNT(R17:R22)=6,(AVERAGE(R20:R22)/AVERAGE(R17:R19))^4-1,"") | T22: 77.4 | U22: =IF(ISNUMBER(T22),T22/T$65*100,"") | V22: =IF(AND(ISNUMBER(T22),ISNUMBER(T21)),T22/T21-1,"") | W22: =IF(AND(ISNUMBER(T22),ISNUMBER(T10)),T22/T10-1,"") | X22: 76.95 | Y22: =IF(COUNT(X17:X22)=6,(AVERAGE(X20:X22)/AVERAGE(X17:X19))^4-1,"") | Z22: 80.2 | AA22: =IF(ISNUMBER(Z22),Z22/Z$65*100,"") | AB22: =IF(AND(ISNUMBER(Z22),ISNUMBER(Z21)),Z22/Z21-1,"") | AC22: =IF(AND(ISNUMBER(Z22),ISNUMBER(Z10)),Z22/Z10-1,"") | AD22: 79.91 | AE22: =IF(COUNT(AD17:AD22)=6,(AVERAGE(AD20:AD22)/AVERAGE(AD17:AD19))^4-1,"") | AF22: 71.17 | AG22: =IF(ISNUMBER(AF22),AF22/AF$65*100,"") | AH22: =IF(AND(ISNUMBER(AF22),ISNUMBER(AF21)),AF22/AF21-1,"") | AI22: =IF(AND(ISNUMBER(AF22),ISNUMBER(AF10)),AF22/AF10-1,"") | AJ22: 71.03 | AK22: =IF(COUNT(AJ17:AJ22)=6,(AVERAGE(AJ20:AJ22)/AVERAGE(AJ17:AJ19))^4-1,"") | AL22: 65.92 | AM22: =IF(ISNUMBER(AL22),AL22/AL$65*100,"") | AN22: =IF(AND(ISNUMBER(AL22),ISNUMBER(AL21)),AL22/AL21-1,"") | AO22: =IF(AND(ISNUMBER(AL22),ISNUMBER(AL10)),AL22/AL10-1,"") | AP22: 65.92 | AQ22: =IF(COUNT(AP17:AP22)=6,(AVERAGE(AP20:AP22)/AVERAGE(AP17:AP19))^4-1,"") | AR22: 77.75 | AS22: =IF(ISNUMBER(AR22),AR22/AR$65*100,"") | AT22: =IF(AND(ISNUMBER(AR22),ISNUMBER(AR21)),AR22/AR21-1,"") | AU22: =IF(AND(ISNUMBER(AR22),ISNUMBER(AR10)),AR22/AR10-1,"") | AV22: 77.4961 | AW22: =IF(COUNT(AV17:AV22)=6,(AVERAGE(AV20:AV22)/AVERAGE(AV17:AV19))^4-1,"")
A23: 42552 | B23: 77.89 | C23: =IF(ISNUMBER(B23),B23/B$65*100,"") | D23: =IF(AND(ISNUMBER(B23),ISNUMBER(B22)),B23/B22-1,"") | E23: =IF(AND(ISNUMBER(B23),ISNUMBER(B11)),B23/B11-1,"") | F23: 77.9 | G23: =IF(COUNT(F18:F23)=6,(AVERAGE(F21:F23)/AVERAGE(F18:F20))^4-1,"") | H23: 82.6 | I23: =IF(ISNUMBER(H23),H23/H$65*100,"") | J23: =IF(AND(ISNUMBER(H23),ISNUMBER(H22)),H23/H22-1,"") | K23: =IF(AND(ISNUMBER(H23),ISNUMBER(H11)),H23/H11-1,"") | L23: 82.59 | M23: =IF(COUNT(L18:L23)=6,(AVERAGE(L21:L23)/AVERAGE(L18:L20))^4-1,"") | N23: 79.8 | O23: =IF(ISNUMBER(N23),N23/N$65*100,"") | P23: =IF(AND(ISNUMBER(N23),ISNUMBER(N22)),N23/N22-1,"") | Q23: =IF(AND(ISNUMBER(N23),ISNUMBER(N11)),N23/N11-1,"") | R23: 79.81 | S23: =IF(COUNT(R18:R23)=6,(AVERAGE(R21:R23)/AVERAGE(R18:R20))^4-1,"") | T23: 75.96 | U23: =IF(ISNUMBER(T23),T23/T$65*100,"") | V23: =IF(AND(ISNUMBER(T23),ISNUMBER(T22)),T23/T22-1,"") | W23: =IF(AND(ISNUMBER(T23),ISNUMBER(T11)),T23/T11-1,"") | X23: 76.9 | Y23: =IF(COUNT(X18:X23)=6,(AVERAGE(X21:X23)/AVERAGE(X18:X20))^4-1,"") | Z23: 81.19 | AA23: =IF(ISNUMBER(Z23),Z23/Z$65*100,"") | AB23: =IF(AND(ISNUMBER(Z23),ISNUMBER(Z22)),Z23/Z22-1,"") | AC23: =IF(AND(ISNUMBER(Z23),ISNUMBER(Z11)),Z23/Z11-1,"") | AD23: 79.96 | AE23: =IF(COUNT(AD18:AD23)=6,(AVERAGE(AD21:AD23)/AVERAGE(AD18:AD20))^4-1,"") | AF23: 71.18 | AG23: =IF(ISNUMBER(AF23),AF23/AF$65*100,"") | AH23: =IF(AND(ISNUMBER(AF23),ISNUMBER(AF22)),AF23/AF22-1,"") | AI23: =IF(AND(ISNUMBER(AF23),ISNUMBER(AF11)),AF23/AF11-1,"") | AJ23: 71.23 | AK23: =IF(COUNT(AJ18:AJ23)=6,(AVERAGE(AJ21:AJ23)/AVERAGE(AJ18:AJ20))^4-1,"") | AL23: 65.26 | AM23: =IF(ISNUMBER(AL23),AL23/AL$65*100,"") | AN23: =IF(AND(ISNUMBER(AL23),ISNUMBER(AL22)),AL23/AL22-1,"") | AO23: =IF(AND(ISNUMBER(AL23),ISNUMBER(AL11)),AL23/AL11-1,"") | AP23: 65.26 | AQ23: =IF(COUNT(AP18:AP23)=6,(AVERAGE(AP21:AP23)/AVERAGE(AP18:AP20))^4-1,"") | AR23: 78.01 | AS23: =IF(ISNUMBER(AR23),AR23/AR$65*100,"") | AT23: =IF(AND(ISNUMBER(AR23),ISNUMBER(AR22)),AR23/AR22-1,"") | AU23: =IF(AND(ISNUMBER(AR23),ISNUMBER(AR11)),AR23/AR11-1,"") | AV23: 77.3705 | AW23: =IF(COUNT(AV18:AV23)=6,(AVERAGE(AV21:AV23)/AVERAGE(AV18:AV20))^4-1,"")
A24: 42583 | B24: 77.93 | C24: =IF(ISNUMBER(B24),B24/B$65*100,"") | D24: =IF(AND(ISNUMBER(B24),ISNUMBER(B23)),B24/B23-1,"") | E24: =IF(AND(ISNUMBER(B24),ISNUMBER(B12)),B24/B12-1,"") | F24: 77.91 | G24: =IF(COUNT(F19:F24)=6,(AVERAGE(F22:F24)/AVERAGE(F19:F21))^4-1,"") | H24: 82.8 | I24: =IF(ISNUMBER(H24),H24/H$65*100,"") | J24: =IF(AND(ISNUMBER(H24),ISNUMBER(H23)),H24/H23-1,"") | K24: =IF(AND(ISNUMBER(H24),ISNUMBER(H12)),H24/H12-1,"") | L24: 82.66 | M24: =IF(COUNT(L19:L24)=6,(AVERAGE(L22:L24)/AVERAGE(L19:L21))^4-1,"") | N24: 79.95 | O24: =IF(ISNUMBER(N24),N24/N$65*100,"") | P24: =IF(AND(ISNUMBER(N24),ISNUMBER(N23)),N24/N23-1,"") | Q24: =IF(AND(ISNUMBER(N24),ISNUMBER(N12)),N24/N12-1,"") | R24: 79.91 | S24: =IF(COUNT(R19:R24)=6,(AVERAGE(R22:R24)/AVERAGE(R19:R21))^4-1,"") | T24: 75.92 | U24: =IF(ISNUMBER(T24),T24/T$65*100,"") | V24: =IF(AND(ISNUMBER(T24),ISNUMBER(T23)),T24/T23-1,"") | W24: =IF(AND(ISNUMBER(T24),ISNUMBER(T12)),T24/T12-1,"") | X24: 76.86 | Y24: =IF(COUNT(X19:X24)=6,(AVERAGE(X22:X24)/AVERAGE(X19:X21))^4-1,"") | Z24: 81.36 | AA24: =IF(ISNUMBER(Z24),Z24/Z$65*100,"") | AB24: =IF(AND(ISNUMBER(Z24),ISNUMBER(Z23)),Z24/Z23-1,"") | AC24: =IF(AND(ISNUMBER(Z24),ISNUMBER(Z12)),Z24/Z12-1,"") | AD24: 80.03 | AE24: =IF(COUNT(AD19:AD24)=6,(AVERAGE(AD22:AD24)/AVERAGE(AD19:AD21))^4-1,"") | AF24: 71.18 | AG24: =IF(ISNUMBER(AF24),AF24/AF$65*100,"") | AH24: =IF(AND(ISNUMBER(AF24),ISNUMBER(AF23)),AF24/AF23-1,"") | AI24: =IF(AND(ISNUMBER(AF24),ISNUMBER(AF12)),AF24/AF12-1,"") | AJ24: 71.44 | AK24: =IF(COUNT(AJ19:AJ24)=6,(AVERAGE(AJ22:AJ24)/AVERAGE(AJ19:AJ21))^4-1,"") | AL24: 64.57 | AM24: =IF(ISNUMBER(AL24),AL24/AL$65*100,"") | AN24: =IF(AND(ISNUMBER(AL24),ISNUMBER(AL23)),AL24/AL23-1,"") | AO24: =IF(AND(ISNUMBER(AL24),ISNUMBER(AL12)),AL24/AL12-1,"") | AP24: 64.57 | AQ24: =IF(COUNT(AP19:AP24)=6,(AVERAGE(AP22:AP24)/AVERAGE(AP19:AP21))^4-1,"") | AR24: 77.69 | AS24: =IF(ISNUMBER(AR24),AR24/AR$65*100,"") | AT24: =IF(AND(ISNUMBER(AR24),ISNUMBER(AR23)),AR24/AR23-1,"") | AU24: =IF(AND(ISNUMBER(AR24),ISNUMBER(AR12)),AR24/AR12-1,"") | AV24: 76.944 | AW24: =IF(COUNT(AV19:AV24)=6,(AVERAGE(AV22:AV24)/AVERAGE(AV19:AV21))^4-1,"")
A25: 42614 | B25: 78.23 | C25: =IF(ISNUMBER(B25),B25/B$65*100,"") | D25: =IF(AND(ISNUMBER(B25),ISNUMBER(B24)),B25/B24-1,"") | E25: =IF(AND(ISNUMBER(B25),ISNUMBER(B13)),B25/B13-1,"") | F25: 77.99 | G25: =IF(COUNT(F20:F25)=6,(AVERAGE(F23:F25)/AVERAGE(F20:F22))^4-1,"") | H25: 83.19 | I25: =IF(ISNUMBER(H25),H25/H$65*100,"") | J25: =IF(AND(ISNUMBER(H25),ISNUMBER(H24)),H25/H24-1,"") | K25: =IF(AND(ISNUMBER(H25),ISNUMBER(H13)),H25/H13-1,"") | L25: 82.74 | M25: =IF(COUNT(L20:L25)=6,(AVERAGE(L23:L25)/AVERAGE(L20:L22))^4-1,"") | N25: 80.2 | O25: =IF(ISNUMBER(N25),N25/N$65*100,"") | P25: =IF(AND(ISNUMBER(N25),ISNUMBER(N24)),N25/N24-1,"") | Q25: =IF(AND(ISNUMBER(N25),ISNUMBER(N13)),N25/N13-1,"") | R25: 79.92 | S25: =IF(COUNT(R20:R25)=6,(AVERAGE(R23:R25)/AVERAGE(R20:R22))^4-1,"") | T25: 77.09 | U25: =IF(ISNUMBER(T25),T25/T$65*100,"") | V25: =IF(AND(ISNUMBER(T25),ISNUMBER(T24)),T25/T24-1,"") | W25: =IF(AND(ISNUMBER(T25),ISNUMBER(T13)),T25/T13-1,"") | X25: 76.92 | Y25: =IF(COUNT(X20:X25)=6,(AVERAGE(X23:X25)/AVERAGE(X20:X22))^4-1,"") | Z25: 80.52 | AA25: =IF(ISNUMBER(Z25),Z25/Z$65*100,"") | AB25: =IF(AND(ISNUMBER(Z25),ISNUMBER(Z24)),Z25/Z24-1,"") | AC25: =IF(AND(ISNUMBER(Z25),ISNUMBER(Z13)),Z25/Z13-1,"") | AD25: 80.16 | AE25: =IF(COUNT(AD20:AD25)=6,(AVERAGE(AD23:AD25)/AVERAGE(AD20:AD22))^4-1,"") | AF25: 70.98 | AG25: =IF(ISNUMBER(AF25),AF25/AF$65*100,"") | AH25: =IF(AND(ISNUMBER(AF25),ISNUMBER(AF24)),AF25/AF24-1,"") | AI25: =IF(AND(ISNUMBER(AF25),ISNUMBER(AF13)),AF25/AF13-1,"") | AJ25: 71.25 | AK25: =IF(COUNT(AJ20:AJ25)=6,(AVERAGE(AJ23:AJ25)/AVERAGE(AJ20:AJ22))^4-1,"") | AL25: 65.24 | AM25: =IF(ISNUMBER(AL25),AL25/AL$65*100,"") | AN25: =IF(AND(ISNUMBER(AL25),ISNUMBER(AL24)),AL25/AL24-1,"") | AO25: =IF(AND(ISNUMBER(AL25),ISNUMBER(AL13)),AL25/AL13-1,"") | AP25: 65.24 | AQ25: =IF(COUNT(AP20:AP25)=6,(AVERAGE(AP23:AP25)/AVERAGE(AP20:AP22))^4-1,"") | AR25: 77.31 | AS25: =IF(ISNUMBER(AR25),AR25/AR$65*100,"") | AT25: =IF(AND(ISNUMBER(AR25),ISNUMBER(AR24)),AR25/AR24-1,"") | AU25: =IF(AND(ISNUMBER(AR25),ISNUMBER(AR13)),AR25/AR13-1,"") | AV25: 77.3483 | AW25: =IF(COUNT(AV20:AV25)=6,(AVERAGE(AV23:AV25)/AVERAGE(AV20:AV22))^4-1,"")
A26: 42644 | B26: 78.41 | C26: =IF(ISNUMBER(B26),B26/B$65*100,"") | D26: =IF(AND(ISNUMBER(B26),ISNUMBER(B25)),B26/B25-1,"") | E26: =IF(AND(ISNUMBER(B26),ISNUMBER(B14)),B26/B14-1,"") | F26: 78.15 | G26: =IF(COUNT(F21:F26)=6,(AVERAGE(F24:F26)/AVERAGE(F21:F23))^4-1,"") | H26: 83.27 | I26: =IF(ISNUMBER(H26),H26/H$65*100,"") | J26: =IF(AND(ISNUMBER(H26),ISNUMBER(H25)),H26/H25-1,"") | K26: =IF(AND(ISNUMBER(H26),ISNUMBER(H14)),H26/H14-1,"") | L26: 82.83 | M26: =IF(COUNT(L21:L26)=6,(AVERAGE(L24:L26)/AVERAGE(L21:L23))^4-1,"") | N26: 80.27 | O26: =IF(ISNUMBER(N26),N26/N$65*100,"") | P26: =IF(AND(ISNUMBER(N26),ISNUMBER(N25)),N26/N25-1,"") | Q26: =IF(AND(ISNUMBER(N26),ISNUMBER(N14)),N26/N14-1,"") | R26: 79.97 | S26: =IF(COUNT(R21:R26)=6,(AVERAGE(R24:R26)/AVERAGE(R21:R23))^4-1,"") | T26: 77.55 | U26: =IF(ISNUMBER(T26),T26/T$65*100,"") | V26: =IF(AND(ISNUMBER(T26),ISNUMBER(T25)),T26/T25-1,"") | W26: =IF(AND(ISNUMBER(T26),ISNUMBER(T14)),T26/T14-1,"") | X26: 77.12 | Y26: =IF(COUNT(X21:X26)=6,(AVERAGE(X24:X26)/AVERAGE(X21:X23))^4-1,"") | Z26: 80.34 | AA26: =IF(ISNUMBER(Z26),Z26/Z$65*100,"") | AB26: =IF(AND(ISNUMBER(Z26),ISNUMBER(Z25)),Z26/Z25-1,"") | AC26: =IF(AND(ISNUMBER(Z26),ISNUMBER(Z14)),Z26/Z14-1,"") | AD26: 80.26 | AE26: =IF(COUNT(AD21:AD26)=6,(AVERAGE(AD24:AD26)/AVERAGE(AD21:AD23))^4-1,"") | AF26: 71.01 | AG26: =IF(ISNUMBER(AF26),AF26/AF$65*100,"") | AH26: =IF(AND(ISNUMBER(AF26),ISNUMBER(AF25)),AF26/AF25-1,"") | AI26: =IF(AND(ISNUMBER(AF26),ISNUMBER(AF14)),AF26/AF14-1,"") | AJ26: 71.12 | AK26: =IF(COUNT(AJ21:AJ26)=6,(AVERAGE(AJ24:AJ26)/AVERAGE(AJ21:AJ23))^4-1,"") | AL26: 66.28 | AM26: =IF(ISNUMBER(AL26),AL26/AL$65*100,"") | AN26: =IF(AND(ISNUMBER(AL26),ISNUMBER(AL25)),AL26/AL25-1,"") | AO26: =IF(AND(ISNUMBER(AL26),ISNUMBER(AL14)),AL26/AL14-1,"") | AP26: 66.28 | AQ26: =IF(COUNT(AP21:AP26)=6,(AVERAGE(AP24:AP26)/AVERAGE(AP21:AP23))^4-1,"") | AR26: 77.78 | AS26: =IF(ISNUMBER(AR26),AR26/AR$65*100,"") | AT26: =IF(AND(ISNUMBER(AR26),ISNUMBER(AR25)),AR26/AR25-1,"") | AU26: =IF(AND(ISNUMBER(AR26),ISNUMBER(AR14)),AR26/AR14-1,"") | AV26: 77.8926 | AW26: =IF(COUNT(AV21:AV26)=6,(AVERAGE(AV24:AV26)/AVERAGE(AV21:AV23))^4-1,"")
A27: 42675 | B27: 78.13 | C27: =IF(ISNUMBER(B27),B27/B$65*100,"") | D27: =IF(AND(ISNUMBER(B27),ISNUMBER(B26)),B27/B26-1,"") | E27: =IF(AND(ISNUMBER(B27),ISNUMBER(B15)),B27/B15-1,"") | F27: 78.26 | G27: =IF(COUNT(F22:F27)=6,(AVERAGE(F25:F27)/AVERAGE(F22:F24))^4-1,"") | H27: 82.8 | I27: =IF(ISNUMBER(H27),H27/H$65*100,"") | J27: =IF(AND(ISNUMBER(H27),ISNUMBER(H26)),H27/H26-1,"") | K27: =IF(AND(ISNUMBER(H27),ISNUMBER(H15)),H27/H15-1,"") | L27: 82.93 | M27: =IF(COUNT(L22:L27)=6,(AVERAGE(L25:L27)/AVERAGE(L22:L24))^4-1,"") | N27: 79.97 | O27: =IF(ISNUMBER(N27),N27/N$65*100,"") | P27: =IF(AND(ISNUMBER(N27),ISNUMBER(N26)),N27/N26-1,"") | Q27: =IF(AND(ISNUMBER(N27),ISNUMBER(N15)),N27/N15-1,"") | R27: 80.11 | S27: =IF(COUNT(R22:R27)=6,(AVERAGE(R25:R27)/AVERAGE(R22:R24))^4-1,"") | T27: 77.63 | U27: =IF(ISNUMBER(T27),T27/T$65*100,"") | V27: =IF(AND(ISNUMBER(T27),ISNUMBER(T26)),T27/T26-1,"") | W27: =IF(AND(ISNUMBER(T27),ISNUMBER(T15)),T27/T15-1,"") | X27: 77.2 | Y27: =IF(COUNT(X22:X27)=6,(AVERAGE(X25:X27)/AVERAGE(X22:X24))^4-1,"") | Z27: 79.59 | AA27: =IF(ISNUMBER(Z27),Z27/Z$65*100,"") | AB27: =IF(AND(ISNUMBER(Z27),ISNUMBER(Z26)),Z27/Z26-1,"") | AC27: =IF(AND(ISNUMBER(Z27),ISNUMBER(Z15)),Z27/Z15-1,"") | AD27: 80.41 | AE27: =IF(COUNT(AD22:AD27)=6,(AVERAGE(AD25:AD27)/AVERAGE(AD22:AD24))^4-1,"") | AF27: 71.24 | AG27: =IF(ISNUMBER(AF27),AF27/AF$65*100,"") | AH27: =IF(AND(ISNUMBER(AF27),ISNUMBER(AF26)),AF27/AF26-1,"") | AI27: =IF(AND(ISNUMBER(AF27),ISNUMBER(AF15)),AF27/AF15-1,"") | AJ27: 71.42 | AK27: =IF(COUNT(AJ22:AJ27)=6,(AVERAGE(AJ25:AJ27)/AVERAGE(AJ22:AJ24))^4-1,"") | AL27: 66.16 | AM27: =IF(ISNUMBER(AL27),AL27/AL$65*100,"") | AN27: =IF(AND(ISNUMBER(AL27),ISNUMBER(AL26)),AL27/AL26-1,"") | AO27: =IF(AND(ISNUMBER(AL27),ISNUMBER(AL15)),AL27/AL15-1,"") | AP27: 66.16 | AQ27: =IF(COUNT(AP22:AP27)=6,(AVERAGE(AP25:AP27)/AVERAGE(AP22:AP24))^4-1,"") | AR27: 77.39 | AS27: =IF(ISNUMBER(AR27),AR27/AR$65*100,"") | AT27: =IF(AND(ISNUMBER(AR27),ISNUMBER(AR26)),AR27/AR26-1,"") | AU27: =IF(AND(ISNUMBER(AR27),ISNUMBER(AR15)),AR27/AR15-1,"") | AV27: 77.8949 | AW27: =IF(COUNT(AV22:AV27)=6,(AVERAGE(AV25:AV27)/AVERAGE(AV22:AV24))^4-1,"")
A28: 42705 | B28: 78.55 | C28: =IF(ISNUMBER(B28),B28/B$65*100,"") | D28: =IF(AND(ISNUMBER(B28),ISNUMBER(B27)),B28/B27-1,"") | E28: =IF(AND(ISNUMBER(B28),ISNUMBER(B16)),B28/B16-1,"") | F28: 78.5 | G28: =IF(COUNT(F23:F28)=6,(AVERAGE(F26:F28)/AVERAGE(F23:F25))^4-1,"") | H28: 83.15 | I28: =IF(ISNUMBER(H28),H28/H$65*100,"") | J28: =IF(AND(ISNUMBER(H28),ISNUMBER(H27)),H28/H27-1,"") | K28: =IF(AND(ISNUMBER(H28),ISNUMBER(H16)),H28/H16-1,"") | L28: 83.01 | M28: =IF(COUNT(L23:L28)=6,(AVERAGE(L26:L28)/AVERAGE(L23:L25))^4-1,"") | N28: 80.28 | O28: =IF(ISNUMBER(N28),N28/N$65*100,"") | P28: =IF(AND(ISNUMBER(N28),ISNUMBER(N27)),N28/N27-1,"") | Q28: =IF(AND(ISNUMBER(N28),ISNUMBER(N16)),N28/N16-1,"") | R28: 80.22 | S28: =IF(COUNT(R23:R28)=6,(AVERAGE(R26:R28)/AVERAGE(R23:R25))^4-1,"") | T28: 77.84 | U28: =IF(ISNUMBER(T28),T28/T$65*100,"") | V28: =IF(AND(ISNUMBER(T28),ISNUMBER(T27)),T28/T27-1,"") | W28: =IF(AND(ISNUMBER(T28),ISNUMBER(T16)),T28/T16-1,"") | X28: 77.51 | Y28: =IF(COUNT(X23:X28)=6,(AVERAGE(X26:X28)/AVERAGE(X23:X25))^4-1,"") | Z28: 80.27 | AA28: =IF(ISNUMBER(Z28),Z28/Z$65*100,"") | AB28: =IF(AND(ISNUMBER(Z28),ISNUMBER(Z27)),Z28/Z27-1,"") | AC28: =IF(AND(ISNUMBER(Z28),ISNUMBER(Z16)),Z28/Z16-1,"") | AD28: 80.56 | AE28: =IF(COUNT(AD23:AD28)=6,(AVERAGE(AD26:AD28)/AVERAGE(AD23:AD25))^4-1,"") | AF28: 71.45 | AG28: =IF(ISNUMBER(AF28),AF28/AF$65*100,"") | AH28: =IF(AND(ISNUMBER(AF28),ISNUMBER(AF27)),AF28/AF27-1,"") | AI28: =IF(AND(ISNUMBER(AF28),ISNUMBER(AF16)),AF28/AF16-1,"") | AJ28: 71.63 | AK28: =IF(COUNT(AJ23:AJ28)=6,(AVERAGE(AJ26:AJ28)/AVERAGE(AJ23:AJ25))^4-1,"") | AL28: 67.35 | AM28: =IF(ISNUMBER(AL28),AL28/AL$65*100,"") | AN28: =IF(AND(ISNUMBER(AL28),ISNUMBER(AL27)),AL28/AL27-1,"") | AO28: =IF(AND(ISNUMBER(AL28),ISNUMBER(AL16)),AL28/AL16-1,"") | AP28: 67.35 | AQ28: =IF(COUNT(AP23:AP28)=6,(AVERAGE(AP26:AP28)/AVERAGE(AP23:AP25))^4-1,"") | AR28: 78.37 | AS28: =IF(ISNUMBER(AR28),AR28/AR$65*100,"") | AT28: =IF(AND(ISNUMBER(AR28),ISNUMBER(AR27)),AR28/AR27-1,"") | AU28: =IF(AND(ISNUMBER(AR28),ISNUMBER(AR16)),AR28/AR16-1,"") | AV28: 78.9246 | AW28: =IF(COUNT(AV23:AV28)=6,(AVERAGE(AV26:AV28)/AVERAGE(AV23:AV25))^4-1,"")
... A145: 46266 | B145: 104.31 | C145: =IF(ISNUMBER(B145),B145/B$65*100,"") | D145: =IF(AND(ISNUMBER(B145),ISNUMBER(B144)),B145/B144-1,"") | E145: =IF(AND(ISNUMBER(B145),ISNUMBER(B133)),B145/B133-1,"") | F145: 104.15 | G145: =IF(COUNT(F140:F145)=6,(AVERAGE(F143:F145)/AVERAGE(F140:F142))^4-1,"") | H145: 103.31 | I145: =IF(ISNUMBER(H145),H145/H$65*100,"") | J145: =IF(AND(ISNUMBER(H145),ISNUMBER(H144)),H145/H144-1,"") | K145: =IF(AND(ISNUMBER(H145),ISNUMBER(H133)),H145/H133-1,"") | L145: 102.99 | M145: =IF(COUNT(L140:L145)=6,(AVERAGE(L143:L145)/AVERAGE(L140:L142))^4-1,"") | N145: 102.97 | O145: =IF(ISNUMBER(N145),N145/N$65*100,"") | P145: =IF(AND(ISNUMBER(N145),ISNUMBER(N144)),N145/N144-1,"") | Q145: =IF(AND(ISNUMBER(N145),ISNUMBER(N133)),N145/N133-1,"") | R145: 102.79 | S145: =IF(COUNT(R140:R145)=6,(AVERAGE(R143:R145)/AVERAGE(R140:R142))^4-1,"") | T145: 104.49 | U145: =IF(ISNUMBER(T145),T145/T$65*100,"") | V145: =IF(AND(ISNUMBER(T145),ISNUMBER(T144)),T145/T144-1,"") | W145: =IF(AND(ISNUMBER(T145),ISNUMBER(T133)),T145/T133-1,"") | X145: 104.36 | Y145: =IF(COUNT(X140:X145)=6,(AVERAGE(X143:X145)/AVERAGE(X140:X142))^4-1,"") | Z145: 104.12 | AA145: =IF(ISNUMBER(Z145),Z145/Z$65*100,"") | AB145: =IF(AND(ISNUMBER(Z145),ISNUMBER(Z144)),Z145/Z144-1,"") | AC145: =IF(AND(ISNUMBER(Z145),ISNUMBER(Z133)),Z145/Z133-1,"") | AD145: 103.91 | AE145: =IF(COUNT(AD140:AD145)=6,(AVERAGE(AD143:AD145)/AVERAGE(AD140:AD142))^4-1,"") | AF145: 101.69 | AG145: =IF(ISNUMBER(AF145),AF145/AF$65*100,"") | AH145: =IF(AND(ISNUMBER(AF145),ISNUMBER(AF144)),AF145/AF144-1,"") | AI145: =IF(AND(ISNUMBER(AF145),ISNUMBER(AF133)),AF145/AF133-1,"") | AJ145: 102.02 | AK145: =IF(COUNT(AJ140:AJ145)=6,(AVERAGE(AJ143:AJ145)/AVERAGE(AJ140:AJ142))^4-1,"") | AL145: 117.57 | AM145: =IF(ISNUMBER(AL145),AL145/AL$65*100,"") | AN145: =IF(AND(ISNUMBER(AL145),ISNUMBER(AL144)),AL145/AL144-1,"") | AO145: =IF(AND(ISNUMBER(AL145),ISNUMBER(AL133)),AL145/AL133-1,"") | AP145: 117.57 | AQ145: =IF(COUNT(AP140:AP145)=6,(AVERAGE(AP143:AP145)/AVERAGE(AP140:AP142))^4-1,"") | AR145: 109.41 | AS145: =IF(ISNUMBER(AR145),AR145/AR$65*100,"") | AT145: =IF(AND(ISNUMBER(AR145),ISNUMBER(AR144)),AR145/AR144-1,"") | AU145: =IF(AND(ISNUMBER(AR145),ISNUMBER(AR133)),AR145/AR133-1,"") | AV145: 107.9734 | AW145: =IF(COUNT(AV140:AV145)=6,(AVERAGE(AV143:AV145)/AVERAGE(AV140:AV142))^4-1,"")

Sheet IT
A1: Italia - indici e variazioni
A2: Blu = dato di fonte; nero = formula. Variazioni in %, 3m/3m su serie destagionalizzata.
B3: HICP generale | H3: Core (escl. energia, alimentari, alcol e tabacchi) | N3: Al netto degli energetici | T3: Beni | Z3: Servizi | AF3: Alimentari (incl. alcol e tabacchi) | AL3: Energia | AR3: Trasporti
A4: Mese | B4: Indice fonte | C4: Base gen20=100 | D4: m/m | E4: a/a | F4: Indice SA | G4: 3m/3m ann. | H4: Indice fonte | I4: Base gen20=100 | J4: m/m | K4: a/a | L4: Indice SA | M4: 3m/3m ann. | N4: Indice fonte | O4: Base gen20=100 | P4: m/m | Q4: a/a | R4: Indice SA | S4: 3m/3m ann. | T4: Indice fonte | U4: Base gen20=100 | V4: m/m | W4: a/a | X4: Indice SA | Y4: 3m/3m ann. | Z4: Indice fonte | AA4: Base gen20=100 | AB4: m/m | AC4: a/a | AD4: Indice SA | AE4: 3m/3m ann. | AF4: Indice fonte | AG4: Base gen20=100 | AH4: m/m | AI4: a/a | AJ4: Indice SA | AK4: 3m/3m ann. | AL4: Indice fonte | AM4: Base gen20=100 | AN4: m/m | AO4: a/a | AP4: Indice SA | AQ4: 3m/3m ann. | AR4: Indice fonte | AS4: Base gen20=100 | AT4: m/m | AU4: a/a | AV4: Indice SA | AW4: 3m/3m ann.
A5: 42005 | B5: 78.9 | C5: =IF(ISNUMBER(B5),B5/B$65*100,"") | F5: 80.0124 | H5: 83.4 | I5: =IF(ISNUMBER(H5),H5/H$65*100,"") | L5: 85.3065 | N5: 81.1 | O5: =IF(ISNUMBER(N5),N5/N$65*100,"") | R5: 82.4303 | T5: 77.1 | U5: =IF(ISNUMBER(T5),T5/T$65*100,"") | X5: 78.5548 | Z5: 82.2 | AA5: =IF(ISNUMBER(Z5),Z5/Z$65*100,"") | AD5: 82.7624 | AF5: 74.9 | AG5: =IF(ISNUMBER(AF5),AF5/AF$65*100,"") | AJ5: 74.5725 | AL5: 67.8 | AM5: =IF(ISNUMBER(AL5),AL5/AL$65*100,"") | AP5: 67.3105 | AR5: 79.5 | AS5: =IF(ISNUMBER(AR5),AR5/AR$65*100,"") | AV5: 80.2136
A6: 42036 | B6: 79 | C6: =IF(ISNUMBER(B6),B6/B$65*100,"") | D6: =IF(AND(ISNUMBER(B6),ISNUMBER(B5)),B6/B5-1,"") | F6: 80.4019 | H6: 83.4 | I6: =IF(ISNUMBER(H6),H6/H$65*100,"") | J6: =IF(AND(ISNUMBER(H6),ISNUMBER(H5)),H6/H5-1,"") | L6: 85.4473 | N6: 81.3 | O6: =IF(ISNUMBER(N6),N6/N$65*100,"") | P6: =IF(AND(ISNUMBER(N6),ISNUMBER(N5)),N6/N5-1,"") | R6: 82.9105 | T6: 77.2 | U6: =IF(ISNUMBER(T6),T6/T$65*100,"") | V6: =IF(AND(ISNUMBER(T6),ISNUMBER(T5)),T6/T5-1,"") | X6: 79.1871 | Z6: 82.4 | AA6: =IF(ISNUMBER(Z6),Z6/Z$65*100,"") | AB6: =IF(AND(ISNUMBER(Z6),ISNUMBER(Z5)),Z6/Z5-1,"") | AD6: 82.9495 | AF6: 75.5 | AG6: =IF(ISNUMBER(AF6),AF6/AF$65*100,"") | AH6: =IF(AND(ISNUMBER(AF6),ISNUMBER(AF5)),AF6/AF5-1,"") | AJ6: 75.3068 | AL6: 67.9 | AM6: =IF(ISNUMBER(AL6),AL6/AL$65*100,"") | AN6: =IF(AND(ISNUMBER(AL6),ISNUMBER(AL5)),AL6/AL5-1,"") | AP6: 67.4864 | AR6: 80 | AS6: =IF(ISNUMBER(AR6),AR6/AR$65*100,"") | AT6: =IF(AND(ISNUMBER(AR6),ISNUMBER(AR5)),AR6/AR5-1,"") | AV6: 80.4178
A7: 42064 | B7: 80.7 | C7: =IF(ISNUMBER(B7),B7/B$65*100,"") | D7: =IF(AND(ISNUMBER(B7),ISNUMBER(B6)),B7/B6-1,"") | F7: 80.3859 | H7: 85.8 | I7: =IF(ISNUMBER(H7),H7/H$65*100,"") | J7: =IF(AND(ISNUMBER(H7),ISNUMBER(H6)),H7/H6-1,"") | L7: 85.489 | N7: 83.1 | O7: =IF(ISNUMBER(N7),N7/N$65*100,"") | P7: =IF(AND(ISNUMBER(N7),ISNUMBER(N6)),N7/N6-1,"") | R7: 82.7906 | T7: 80.2 | U7: =IF(ISNUMBER(T7),T7/T$65*100,"") | V7: =IF(AND(ISNUMBER(T7),ISNUMBER(T6)),T7/T6-1,"") | X7: 79.4261 | Z7: 82.4 | AA7: =IF(ISNUMBER(Z7),Z7/Z$65*100,"") | AB7: =IF(AND(ISNUMBER(Z7),ISNUMBER(Z6)),Z7/Z6-1,"") | AD7: 82.7688 | AF7: 75.4 | AG7: =IF(ISNUMBER(AF7),AF7/AF$65*100,"") | AH7: =IF(AND(ISNUMBER(AF7),ISNUMBER(AF6)),AF7/AF6-1,"") | AJ7: 75.2014 | AL7: 69.2 | AM7: =IF(ISNUMBER(AL7),AL7/AL$65*100,"") | AN7: =IF(AND(ISNUMBER(AL7),ISNUMBER(AL6)),AL7/AL6-1,"") | AP7: 68.6951 | AR7: 81 | AS7: =IF(ISNUMBER(AR7),AR7/AR$65*100,"") | AT7: =IF(AND(ISNUMBER(AR7),ISNUMBER(AR6)),AR7/AR6-1,"") | AV7: 81.4212
A8: 42095 | B8: 81.1 | C8: =IF(ISNUMBER(B8),B8/B$65*100,"") | D8: =IF(AND(ISNUMBER(B8),ISNUMBER(B7)),B8/B7-1,"") | F8: 80.4275 | H8: 86.5 | I8: =IF(ISNUMBER(H8),H8/H$65*100,"") | J8: =IF(AND(ISNUMBER(H8),ISNUMBER(H7)),H8/H7-1,"") | L8: 85.4834 | N8: 83.6 | O8: =IF(ISNUMBER(N8),N8/N$65*100,"") | P8: =IF(AND(ISNUMBER(N8),ISNUMBER(N7)),N8/N7-1,"") | R8: 82.7801 | T8: 80.5 | U8: =IF(ISNUMBER(T8),T8/T$65*100,"") | V8: =IF(AND(ISNUMBER(T8),ISNUMBER(T7)),T8/T7-1,"") | X8: 79.4514 | Z8: 82.9 | AA8: =IF(ISNUMBER(Z8),Z8/Z$65*100,"") | AB8: =IF(AND(ISNUMBER(Z8),ISNUMBER(Z7)),Z8/Z7-1,"") | AD8: 82.7081 | AF8: 75.4 | AG8: =IF(ISNUMBER(AF8),AF8/AF$65*100,"") | AH8: =IF(AND(ISNUMBER(AF8),ISNUMBER(AF7)),AF8/AF7-1,"") | AJ8: 75.284 | AL8: 68.4 | AM8: =IF(ISNUMBER(AL8),AL8/AL$65*100,"") | AN8: =IF(AND(ISNUMBER(AL8),ISNUMBER(AL7)),AL8/AL7-1,"") | AP8: 68.7539 | AR8: 81.4 | AS8: =IF(ISNUMBER(AR8),AR8/AR$65*100,"") | AT8: =IF(AND(ISNUMBER(AR8),ISNUMBER(AR7)),AR8/AR7-1,"") | AV8: 81.605
A9: 42125 | B9: 81.2 | C9: =IF(ISNUMBER(B9),B9/B$65*100,"") | D9: =IF(AND(ISNUMBER(B9),ISNUMBER(B8)),B9/B8-1,"") | F9: 80.5283 | H9: 86.6 | I9: =IF(ISNUMBER(H9),H9/H$65*100,"") | J9: =IF(AND(ISNUMBER(H9),ISNUMBER(H8)),H9/H8-1,"") | L9: 85.6309 | N9: 83.7 | O9: =IF(ISNUMBER(N9),N9/N$65*100,"") | P9: =IF(AND(ISNUMBER(N9),ISNUMBER(N8)),N9/N8-1,"") | R9: 82.8983 | T9: 80.7 | U9: =IF(ISNUMBER(T9),T9/T$65*100,"") | V9: =IF(AND(ISNUMBER(T9),ISNUMBER(T8)),T9/T8-1,"") | X9: 79.5841 | Z9: 83 | AA9: =IF(ISNUMBER(Z9),Z9/Z$65*100,"") | AB9: =IF(AND(ISNUMBER(Z9),ISNUMBER(Z8)),Z9/Z8-1,"") | AD9: 82.926 | AF9: 75.5 | AG9: =IF(ISNUMBER(AF9),AF9/AF$65*100,"") | AH9: =IF(AND(ISNUMBER(AF9),ISNUMBER(AF8)),AF9/AF8-1,"") | AJ9: 75.1703 | AL9: 69 | AM9: =IF(ISNUMBER(AL9),AL9/AL$65*100,"") | AN9: =IF(AND(ISNUMBER(AL9),ISNUMBER(AL8)),AL9/AL8-1,"") | AP9: 69.1673 | AR9: 81.8 | AS9: =IF(ISNUMBER(AR9),AR9/AR$65*100,"") | AT9: =IF(AND(ISNUMBER(AR9),ISNUMBER(AR8)),AR9/AR8-1,"") | AV9: 81.8524
A10: 42156 | B10: 81.3 | C10: =IF(ISNUMBER(B10),B10/B$65*100,"") | D10: =IF(AND(ISNUMBER(B10),ISNUMBER(B9)),B10/B9-1,"") | F10: 80.5641 | G10: =IF(COUNT(F5:F10)=6,(AVERAGE(F8:F10)/AVERAGE(F5:F7))^4-1,"") | H10: 86.7 | I10: =IF(ISNUMBER(H10),H10/H$65*100,"") | J10: =IF(AND(ISNUMBER(H10),ISNUMBER(H9)),H10/H9-1,"") | L10: 85.6755 | M10: =IF(COUNT(L5:L10)=6,(AVERAGE(L8:L10)/AVERAGE(L5:L7))^4-1,"") | N10: 83.8 | O10: =IF(ISNUMBER(N10),N10/N$65*100,"") | P10: =IF(AND(ISNUMBER(N10),ISNUMBER(N9)),N10/N9-1,"") | R10: 82.9612 | S10: =IF(COUNT(R5:R10)=6,(AVERAGE(R8:R10)/AVERAGE(R5:R7))^4-1,"") | T10: 80.7 | U10: =IF(ISNUMBER(T10),T10/T$65*100,"") | V10: =IF(AND(ISNUMBER(T10),ISNUMBER(T9)),T10/T9-1,"") | X10: 79.621 | Y10: =IF(COUNT(X5:X10)=6,(AVERAGE(X8:X10)/AVERAGE(X5:X7))^4-1,"") | Z10: 83.1 | AA10: =IF(ISNUMBER(Z10),Z10/Z$65*100,"") | AB10: =IF(AND(ISNUMBER(Z10),ISNUMBER(Z9)),Z10/Z9-1,"") | AD10: 82.8361 | AE10: =IF(COUNT(AD5:AD10)=6,(AVERAGE(AD8:AD10)/AVERAGE(AD5:AD7))^4-1,"") | AF10: 75.5 | AG10: =IF(ISNUMBER(AF10),AF10/AF$65*100,"") | AH10: =IF(AND(ISNUMBER(AF10),ISNUMBER(AF9)),AF10/AF9-1,"") | AJ10: 75.216 | AK10: =IF(COUNT(AJ5:AJ10)=6,(AVERAGE(AJ8:AJ10)/AVERAGE(AJ5:AJ7))^4-1,"") | AL10: 69 | AM10: =IF(ISNUMBER(AL10),AL10/AL$65*100,"") | AN10: =IF(AND(ISNUMBER(AL10),ISNUMBER(AL9)),AL10/AL9-1,"") | AP10: 69.2381 | AQ10: =IF(COUNT(AP5:AP10)=6,(AVERAGE(AP8:AP10)/AVERAGE(AP5:AP7))^4-1,"") | AR10: 82 | AS10: =IF(ISNUMBER(AR10),AR10/AR$65*100,"") | AT10: =IF(AND(ISNUMBER(AR10),ISNUMBER(AR9)),AR10/AR9-1,"") | AV10: 81.7525 | AW10: =IF(COUNT(AV5:AV10)=6,(AVERAGE(AV8:AV10)/AVERAGE(AV5:AV7))^4-1,"")
A11: 42186 | B11: 79.7 | C11: =IF(ISNUMBER(B11),B11/B$65*100,"") | D11: =IF(AND(ISNUMBER(B11),ISNUMBER(B10)),B11/B10-1,"") | F11: 80.5178 | G11: =IF(COUNT(F6:F11)=6,(AVERAGE(F9:F11)/AVERAGE(F6:F8))^4-1,"") | H11: 84.6 | I11: =IF(ISNUMBER(H11),H11/H$65*100,"") | J11: =IF(AND(ISNUMBER(H11),ISNUMBER(H10)),H11/H10-1,"") | L11: 85.6195 | M11: =IF(COUNT(L6:L11)=6,(AVERAGE(L9:L11)/AVERAGE(L6:L8))^4-1,"") | N11: 82 | O11: =IF(ISNUMBER(N11),N11/N$65*100,"") | P11: =IF(AND(ISNUMBER(N11),ISNUMBER(N10)),N11/N10-1,"") | R11: 82.8695 | S11: =IF(COUNT(R6:R11)=6,(AVERAGE(R9:R11)/AVERAGE(R6:R8))^4-1,"") | T11: 77.7 | U11: =IF(ISNUMBER(T11),T11/T$65*100,"") | V11: =IF(AND(ISNUMBER(T11),ISNUMBER(T10)),T11/T10-1,"") | X11: 79.4697 | Y11: =IF(COUNT(X6:X11)=6,(AVERAGE(X9:X11)/AVERAGE(X6:X8))^4-1,"") | Z11: 83.5 | AA11: =IF(ISNUMBER(Z11),Z11/Z$65*100,"") | AB11: =IF(AND(ISNUMBER(Z11),ISNUMBER(Z10)),Z11/Z10-1,"") | AD11: 82.8995 | AE11: =IF(COUNT(AD6:AD11)=6,(AVERAGE(AD9:AD11)/AVERAGE(AD6:AD8))^4-1,"") | AF11: 74.8 | AG11: =IF(ISNUMBER(AF11),AF11/AF$65*100,"") | AH11: =IF(AND(ISNUMBER(AF11),ISNUMBER(AF10)),AF11/AF10-1,"") | AJ11: 75.1052 | AK11: =IF(COUNT(AJ6:AJ11)=6,(AVERAGE(AJ9:AJ11)/AVERAGE(AJ6:AJ8))^4-1,"") | AL11: 68.6 | AM11: =IF(ISNUMBER(AL11),AL11/AL$65*100,"") | AN11: =IF(AND(ISNUMBER(AL11),ISNUMBER(AL10)),AL11/AL10-1,"") | AP11: 68.9168 | AQ11: =IF(COUNT(AP6:AP11)=6,(AVERAGE(AP9:AP11)/AVERAGE(AP6:AP8))^4-1,"") | AR11: 82.7 | AS11: =IF(ISNUMBER(AR11),AR11/AR$65*100,"") | AT11: =IF(AND(ISNUMBER(AR11),ISNUMBER(AR10)),AR11/AR10-1,"") | AV11: 81.9735 | AW11: =IF(COUNT(AV6:AV11)=6,(AVERAGE(AV9:AV11)/AVERAGE(AV6:AV8))^4-1,"")
